Workbook

Sheet PORTADA
A2: IMPULSA 2026: CASE STUDY SLOTTING
A4: CD Aldeas - Villa El Salvador | Inchcape Perú

Sheet RESUMEN
A1: 📊 KPIs: ACTUAL vs META
A3: MÉTRICA | B3: ACTUAL | C3: META | D3: MEJORA REQUERIDA
A4: Tiempo promedio | B4: 12.64 min/pedido | C4: 9.48 min/pedido | D4: -25%
A5: Productividad | B5: 11.64 SKU/HH | C5: 13.39 SKU/HH | D5: +15%

Sheet GLOSARIO_GUÍA
A1: TÉRMINO | B1: DEFINICIÓN
A2: SKU | B2: Stock Keeping Unit - Código único del producto
A3: ROTACIÓN | B3: Cantidad de veces que se despacha en 6 meses
A4: ABC | B4: A=Alta rotación, B=Media, C=Baja
A5: VOL_M3 | B5: Volumen en metros cúbicos
A6: ZONA | B6: Área física del almacén
A7: TIEMPO | B7: Minutos que demora buscar y recoger
A8: CAPACIDAD | B8: Volumen máximo que cabe en la zona
A11: PASOS PARA RESOLVER
A12: 1. VER | B12: Abre STOCK_ACTUAL, LAYOUT_CD y EXTRACTO_PEDIDOS
A13: 2. ENTENDER | B13: Entiende por qué toma 12.64 min/pedido HOY
A14: 3. PROPONER | B14: Reasigna SKUs a zonas en CONSTRUYE_TU_SLOTTING
A15: 4. VALIDAR | B15: Verifica que caben en capacidades (OCUPACIÓN)
A16: 5. CALCULAR | B16: Calcula el nuevo tiempo (suma tiempos de zonas)
A17: 6. COMPARAR | B17: ¿Logras bajar a 9.48 min (-25%)?

Sheet HALLAZGOS_PRELIMINARES
B2: HALLAZGOS PRELIMINARES DEL DATASET
B3: Inchcape Perú · CD Aldeas · MVP Sistema Inteligente de Reslotting · Base: 100 SKU (muestra académica de un universo de +55,000)
B5: TESIS CENTRAL DEL DIAGNÓSTICO
B6: La ubicación actual de los SKU en el CD Aldeas no guarda relación estadística con su rotación (correlación = -0.068). El slotting vigente es, a efectos prácticos, aleatorio respecto a la demanda. Esto convierte al reslotting en una oportunidad de eficiencia de primer orden y no en un ajuste marginal: 18 SKU clase A mal ubicados concentran un ahorro potencial de 33,015 minutos de picking en 6 meses, equivalente al 25.8% del esfuerzo total de picking de la muestra.
B9: 1. CINCO INSIGHTS CLAVE
B10: INSIGHT | C10: EVIDENCIA EN EL DATASET | D10: MÉTRICA
B11: I1. El slotting actual es aleatorio respecto a la rotación | C11: La correlación entre rotación (unid. despachadas 6M) y tiempo de acceso a la zona asignada es prácticamente nula. No existe evidencia de que la asignación de ubicaciones haya respondido a criterios de demanda: el tiempo promedio ponderado por rotación (4.30 min) es casi idéntico al promedio simple (4.36 min), cuando un slotting optimizado debería mostrar el ponderado muy por debajo del simple. | D11: ="Correl. = "&TEXT(ANALYTICS_BASE!$Q$111,"0.000")&CHAR(10)&"Ponderado "&TEXT(ANALYTICS_BASE!$Q$101,"0.00")&" min vs simple "&TEXT(ANALYTICS_BASE!$Q$102,"0.00")&" min" -> Correl. = -0.068 Ponderado 4.30 min vs simple 4.36 min
B12: I2. La mitad de los SKU de clase A está en zonas lejanas | C12: De los 39 SKU clase A, 20 están ubicados en zonas con tiempo de acceso superior a 4 minutos (CLUSTER, RACK BALDA, RACK SIMPLE, MEZANNINE, LLANTAS). En paralelo, 10 SKU clase C ocupan las zonas premium PISO y UBICACIÓN RECIBO (≤2.01 min). Es un doble desperdicio simétrico: lo que rota lejos y lo que no rota cerca. | D12: =TEXT(ANALYTICS_BASE!$Q$104,"0")&" de 39 SKU A mal ubicados ("&TEXT(ANALYTICS_BASE!$Q$105,"0.0%")&")"&CHAR(10)&TEXT(ANALYTICS_BASE!$Q$106,"0")&" SKU C en zona premium" -> 20 de 39 SKU A mal ubicados (51.3%) 10 SKU C en zona premium
B13: I3. El ABC del dataset es anormalmente plano | C13: Los 39 SKU clase A explican solo el 55.0% de la rotación total, y la clase C todavía representa el 12.3%. Un ABC típico de repuestos concentra ~80% de la demanda en ~20% de los SKU. La estructura 39/35/26 sugiere un corte por terciles y no por umbral de concentración económica. | D13: ="A: "&TEXT(ANALYTICS_BASE!$R$5,"0%")&" SKU = "&TEXT(ANALYTICS_BASE!$T$5,"0.0%")&" rotación"&CHAR(10)&"C: "&TEXT(ANALYTICS_BASE!$R$7,"0%")&" SKU = "&TEXT(ANALYTICS_BASE!$T$7,"0.0%")&" rotación" -> A: 39% SKU = 55.0% rotación C: 26% SKU = 12.3% rotación
B14: I4. El costo operativo se concentra en LLANTAS y RACK SIMPLE | C14: LLANTAS es la zona más costosa del CD (8.04 min, 100 m de distancia) y a la vez la que más esfuerzo de picking absorbe: 32,924 min-pick en 6 meses con solo 15 SKU. Sumada a RACK SIMPLE (26,895) y MEZANNINE (20,249), estas tres zonas explican 80,067 min-pick, el 62.5% del esfuerzo total, con apenas 40 SKU. | D14: ="LLANTAS: "&TEXT(ANALYTICS_BASE!$AA$26,"#,##0")&" min-pick"&CHAR(10)&"3 zonas = "&TEXT((ANALYTICS_BASE!$AA$26+ANALYTICS_BASE!$AA$24+ANALYTICS_BASE!$AA$27)/ANALYTICS_BASE!$Q$103,"0.0%")&" del esfuerzo" -> LLANTAS: 32,924 min-pick 3 zonas = 62.5% del esfuerzo
B15: I5. La capacidad física NO es la restricción en esta muestra | C15: Los 100 SKU ocupan 26.16 m³ sobre una capacidad instalada de 2,680 m³: 0.98% de utilización volumétrica. Ninguna zona supera el 1.9% de uso. Además, la zona LATERALES (220 m³) no tiene ningún SKU asignado. El cuello de botella del reslotting no será el espacio, sino las reglas de negocio y las restricciones de manipulación. | D15: ="Ocupación global: "&TEXT(ANALYTICS_BASE!$Q$110,"0.00%")&CHAR(10)&TEXT(ANALYTICS_BASE!$Q$112,"0")&" zona sin SKU asignado" -> Ocupación global: 0.98% 1 zona sin SKU asignado
B18: 2. CINCO OPORTUNIDADES POTENCIALES
B19: OPORTUNIDAD | C19: DESCRIPCIÓN Y BASE DE CÁLCULO | D19: IMPACTO CUANTIFICADO
B20: O1. Reslotting quirúrgico de 18 SKU clase A | C20: Reubicar los 18 SKU clase A que hoy están en LLANTAS, MEZANNINE, RACK SIMPLE y RACK BALDA hacia PISO (1.6 min) libera el mayor ahorro por unidad de esfuerzo del proyecto. Es una intervención de 18 movimientos — no un reacomodo masivo — sobre un portafolio de 100 SKU. | D20: =TEXT(ANALYTICS_BASE!$W$76,"#,##0")&" min-pick ahorrados (6M)"&CHAR(10)&TEXT(ANALYTICS_BASE!$Q$108,"0.0%")&" sobre esos SKU"&CHAR(10)&TEXT(ANALYTICS_BASE!$Q$109,"0.0%")&" del CD total" -> 33,015 min-pick ahorrados (6M) 73.3% sobre esos SKU 25.8% del CD total
B21: O2. Intercambio simétrico A-lejano por C-cercano | C21: Existen 10 SKU clase C en zonas premium y 20 SKU clase A en zonas lejanas. Un intercambio directo evita la necesidad de crear espacio nuevo: cada SKU A que sube a PISO desplaza a un SKU C hacia la zona liberada. Operativamente es un swap, con costo de mano de obra acotado y sin inversión en infraestructura. | D21: ="10 swaps directos disponibles"&CHAR(10)&"Sin inversión en capacidad"&CHAR(10)&"(ocupación actual: "&TEXT(ANALYTICS_BASE!$Q$110,"0.0%")&")" -> 10 swaps directos disponibles Sin inversión en capacidad (ocupación actual: 1.0%)
B22: O3. Activar la zona LATERALES, hoy ociosa | C22: LATERALES figura en el layout con 220 m³ de capacidad y 5.63 min de acceso, pero no tiene ningún SKU asignado en la muestra. Puede absorber SKU de clase C de baja rotación desplazados desde zonas premium, o servir como buffer de reserva durante la ejecución del reslotting. | D22: =TEXT(_xlfn.XLOOKUP("14. LATERALES",LAYOUT_CD!$A$2:$A$10,LAYOUT_CD!$D$2:$D$10),"#,##0")&" m³ disponibles"&CHAR(10)&"0 SKU asignados hoy" -> 220 m³ disponibles 0 SKU asignados hoy
B23: O4. Rediseñar el criterio de clasificación: de ABC a min-pick | C23: El indicador rotación × tiempo de acceso (min-pick) ya calculado por SKU en ANALYTICS_BASE ordena el portafolio por costo operativo real y no por volumen de salida. Sustituir el ABC por esta métrica como criterio de priorización permite dirigir el esfuerzo a los SKU que efectivamente consumen horas-hombre. | D23: ="Base actual: "&TEXT(ANALYTICS_BASE!$Q$103,"#,##0")&" min-pick/6M"&CHAR(10)&"≈ "&TEXT(ANALYTICS_BASE!$Q$103/60,"#,##0")&" horas-hombre de picking" -> Base actual: 128,067 min-pick/6M ≈ 2,134 horas-hombre de picking
B24: O5. Escalar el MVP al universo de +55,000 SKU | C24: La lógica construida es paramétrica: se alimenta de rotación, zona, tiempo de acceso, peso y volumen. Aplicada al universo real, el mismo motor puede rankear candidatos de reslotting de forma continua. El dataset actual representa el 0.18% del universo, por lo que el modelo debe validarse antes de extrapolar el ahorro. | D24: ="Muestra = "&TEXT(100/55000,"0.00%")&" del universo"&CHAR(10)&"Motor paramétrico reutilizable" -> Muestra = 0.18% del universo Motor paramétrico reutilizable
B27: 3. CINCO RIESGOS DE DECIDIR SOLO CON ABC
B28: RIESGO | C28: POR QUÉ IMPORTA — EVIDENCIA EN EL DATASET | D28: SEÑAL DE ALERTA
B29: R1. El ABC ignora el costo de acceso | C29: Dos SKU con idéntica rotación generan un costo de picking radicalmente distinto según su zona: 1.6 min en PISO frente a 8.04 min en LLANTAS, una diferencia de 5x. El ABC los trata igual. Priorizar por clase A sin ponderar el tiempo movería SKU que ya están bien ubicados y dejaría intactos SKU B costosos. | D29: Diferencial de 5.0x en tiempo de acceso entre zona más rápida y más lenta
B30: R2. El ABC ignora restricciones físicas de peso | C30: El dataset contiene 24 SKU que superan los 40 kg, repartidos de forma casi uniforme entre las cinco familias (4 a 5 cada una). Un SKU clase A de 49 kg no puede ubicarse en MEZANNINE ni en un nivel alto de rack por ergonomía y seguridad, por más que su rotación lo justifique. El ABC no captura esta restricción. | D30: =TEXT(SUM(ANALYTICS_BASE!$X$85:$X$89),"0")&" SKU superan 40 kg"&CHAR(10)&"Máx. "&TEXT(MAX(ANALYTICS_BASE!$U$85:$U$89),"0.0")&" kg" -> 24 SKU superan 40 kg Máx. 49.3 kg
B31: R3. La muestra es estadísticamente insuficiente | C31: 100 SKU representan el 0.18% de un universo de +55,000. El dataset está perfectamente balanceado (20 SKU por familia, 5 familias), lo que indica diseño académico y no una extracción aleatoria del maestro real. Extrapolar el ahorro de 33,015 min-pick al universo completo carecería de base estadística. | D31: 20 SKU por familia exactos: muestra diseñada, no aleatoria
B32: R4. El ABC estático ignora estacionalidad y ciclo de vida | C32: La rotación disponible es un agregado de 6 meses, sin desglose temporal. Un SKU puede ser clase A por un pico estacional puntual y clase C el resto del año. Reubicar a zona premium con base en un agregado semestral corre el riesgo de congelar una ubicación óptima para un patrón de demanda ya extinguido. | D32: Rotación agregada 6M sin serie mensual: estacionalidad no observable
B33: R5. El ABC por unidades ignora la estructura del pedido | C33: El costo real de picking depende de la frecuencia de visita a la ubicación (número de líneas de pedido), no del total de unidades despachadas. Un SKU con 500 unidades en 5 pedidos exige 5 viajes; otro con 300 unidades en 100 pedidos exige 100. El segundo es mucho más crítico para el slotting, y el ABC por unidades lo clasificaría por debajo. | D33: Se requiere n° de líneas por SKU, no solo unidades despachadas
B36: 4. VARIABLES ADICIONALES QUE DEBERÍAN SOLICITARSE A INCHCAPE
B37: VARIABLE SOLICITADA | C37: POR QUÉ ES NECESARIA — QUÉ LIMITACIÓN ACTUAL RESUELVE | D37: PRIORIDAD
B38: Líneas de pedido por SKU (frecuencia de visita) | C38: Es la variable más crítica que falta. El slotting se optimiza por número de visitas a la ubicación, no por unidades despachadas. La hoja PEDIDOS ACTUAL contiene 1,500 registros de pedidos que podrían permitir derivar esta frecuencia si se confirma su estructura y trazabilidad al SKU. | D38: CRÍTICA
B39: Serie mensual de rotación (24 meses) | C39: Permite separar demanda estructural de picos estacionales y detectar SKU en fase de declive o lanzamiento. Sin esta serie, cualquier reslotting se ancla a una foto semestral y no a una tendencia. Habilita además un ABC dinámico con revisión trimestral. | D39: CRÍTICA
B40: Afinidad entre SKU (co-ocurrencia en pedidos) | C40: Los SKU que se piden juntos deben almacenarse juntos para reducir el recorrido total de la ruta de picking, no solo el tiempo de acceso individual. Sin análisis de canasta, el reslotting optimiza SKU aislados e ignora la ruta completa, que es donde reside el mayor ahorro en CD de repuestos. | D40: ALTA
B41: Costo de mano de obra por minuto de picking | C41: Convierte los 33,015 min-pick de ahorro identificado en un beneficio económico expresado en soles, condición indispensable para construir el caso de negocio y comparar el ahorro contra el costo de ejecutar los movimientos. | D41: ALTA
B42: Capacidad por ubicación individual y reglas de almacenaje | C42: El layout entrega capacidad agregada por zona (m³), pero el reslotting se ejecuta a nivel de ubicación específica. Se requiere el detalle de posiciones, límites de peso por nivel de rack, restricciones de altura y compatibilidad de producto (p. ej. lubricantes y su tratamiento como material inflamable). | D42: ALTA
B43: Costo de ejecución del movimiento por SKU | C43: Mover un SKU tiene un costo puntual (mano de obra, equipo, riesgo de error de inventario). Sin este dato no puede calcularse el periodo de recuperación de cada reubicación ni definirse un umbral mínimo de ahorro que justifique el movimiento. | D43: MEDIA
B44: Cobertura de stock y política de reposición | C44: Determina cuánto espacio necesita reservarse por SKU de forma sostenida. La ocupación del 0.98% observada refleja una foto puntual de inventario; sin conocer los niveles máximos de reposición, el dimensionamiento de las ubicaciones premium sería incorrecto. | D44: MEDIA
B45: Ubicación física exacta y coordenadas de recorrido | C45: El tiempo de acceso disponible es un promedio por zona. Para un motor de reslotting real se necesita la distancia y el tiempo por posición individual, junto con el trazado de pasillos, a fin de calcular rutas y no solo accesos punto a punto. | D45: MEDIA
B48: 5. PREGUNTAS PARA LA REUNIÓN CON EL EXPERTO LOGÍSTICO
B49: ÁMBITO | C49: PREGUNTA — DERIVADA DE UN HALLAZGO CONCRETO DEL DATASET | D49: HIPÓTESIS A VALIDAR
B50: Criterio de slotting vigente | C50: La correlación entre rotación y tiempo de acceso es -0.068, es decir, nula. ¿Existe hoy una política formal de asignación de ubicaciones, o el slotting se ha construido históricamente por disponibilidad de espacio al momento de la recepción? | D50: El slotting responde a disponibilidad, no a diseño
B51: Zona LLANTAS | C51: LLANTAS concentra 32,924 min-pick (la cifra más alta del CD) con solo 15 SKU y 8.04 min de acceso. ¿Es una zona físicamente dedicada por dimensión del producto, o podrían reubicarse esos SKU de clase A a zonas más cercanas? | D51: La restricción es dimensional y no reubicable
B52: Zona LATERALES | C52: LATERALES aparece en el layout con 220 m³ y 5.63 min de acceso, pero sin ningún SKU asignado en la muestra. ¿Está realmente vacía, se usa para otra categoría fuera del alcance del dataset, o está inhabilitada? | D52: Existe capacidad disponible no considerada
...

Sheet MAESTRO_SKUs
A1: SKU | B1: MARCA | C1: FAMILIA | D1: VOLUMEN_M3 | E1: PESO_KG
A2: SKU00001 | B2: Marca A | C2: Filtros | D2: 0.21854305 | E2: 2.0557447
A3: SKU00002 | B3: Marca B | C3: Lubricantes | D3: 0.47782144 | E3: 32.002315
A4: SKU00003 | B4: Marca C | C4: Pastillas | D4: 0.37939727 | E4: 16.060621 | G4: FAMILIA | H4: CANT | J4: MARCAS | K4: CANT
A5: SKU00004 | B5: Marca D | C5: Correas | D5: 0.31939632 | E5: 25.674249 | G5: FILTROS | H5: =COUNTIF(C2:C101,"*Filtros*") -> 20 | J5: MARCA A | K5: =COUNTIF(B2:B101,"*Marca A*") -> 20
A6: SKU00005 | B6: Marca E | C6: Soportes | D6: 0.12020839 | E6: 45.42454 | G6: LUBRICANTES | H6: =COUNTIF($C$2:$C$101,"*Lubricantes*") -> 20 | J6: MARCA B | K6: =COUNTIF(B2:B101,"*Marca B*") -> 20
A7: SKU00006 | B7: Marca A | C7: Filtros | D7: 0.12019753 | E7: 12.839965 | G7: PASTILLAS | H7: =COUNTIF($C$2:$C$101,"*Pastillas*") -> 20 | J7: MARCA C | K7: =COUNTIF($B$2:$B$103,"*Marca C*") -> 20
A8: SKU00007 | B8: Marca B | C8: Lubricantes | D8: 0.076137625 | E8: 20.813955 | G8: CORREAS | H8: =COUNTIF($C$2:$C$101,"Correas") -> 20 | J8: MARCA D | K8: =COUNTIF($B$2:$B$103,"*Marca D*") -> 20
A9: SKU00008 | B9: Marca C | C9: Pastillas | D9: 0.43977927 | E9: 37.899781 | G9: SOPORTES | H9: =COUNTIF(C3:C102,"*Soportes*") -> 20 | J9: MARCA E | K9: =COUNTIF($B$2:$B$103,"*Marca E*") -> 20
A10: SKU00009 | B10: Marca D | C10: Correas | D10: 0.32050176 | E10: 11.825509
A11: SKU00010 | B11: Marca E | C11: Soportes | D11: 0.36863266 | E11: 4.3105055
A12: SKU00011 | B12: Marca A | C12: Filtros | D12: 0.059263022 | E12: 14.842697 | G12: TOTAL SKU | H12: =COUNTIF(C2:C101,"*") -> 100
A13: SKU00012 | B13: Marca B | C13: Lubricantes | D13: 0.48645943 | E13: 8.4804537
A14: SKU00013 | B14: Marca C | C14: Pastillas | D14: 0.42459919 | E14: 46.520034
A15: SKU00014 | B15: Marca D | C15: Correas | D15: 0.1455526 | E15: 40.501959
A16: SKU00015 | B16: Marca E | C16: Soportes | D16: 0.13182124 | E16: 31.853486
A17: SKU00016 | B17: Marca A | C17: Filtros | D17: 0.13253203 | E17: 43.637299
A18: SKU00017 | B18: Marca B | C18: Lubricantes | D18: 0.18690901 | E18: 40.281768
A19: SKU00018 | B19: Marca C | C19: Pastillas | D19: 0.28614039 | E19: 9.7352179
A20: SKU00019 | B20: Marca D | C20: Correas | D20: 0.24437526 | E20: 44.68167
A21: SKU00020 | B21: Marca E | C21: Soportes | D21: 0.18105311 | E21: 27.197441
A22: SKU00021 | B22: Marca A | C22: Filtros | D22: 0.3253338 | E22: 40.468288
A23: SKU00022 | B23: Marca B | C23: Lubricantes | D23: 0.11277224 | E23: 44.856519
A24: SKU00023 | B24: Marca C | C24: Pastillas | D24: 0.18146509 | E24: 16.241172
... A101: SKU00100 | B101: Marca E | C101: Soportes | D101: 0.098551142 | E101: 39.10384

Sheet ROTACIÓN
A1: SKU | B1: ROTACION_6M | C1: ABC
A2: SKU00085 | B2: 496 | C2: A
A3: SKU00078 | B3: 485 | C3: A
A4: SKU00026 | B4: 484 | C4: A
A5: SKU00069 | B5: 479 | C5: A
A6: SKU00005 | B6: 465 | C6: A
A7: SKU00100 | B7: 460 | C7: A
A8: SKU00062 | B8: 453 | C8: A
A9: SKU00054 | B9: 452 | C9: A
A10: SKU00018 | B10: 451 | C10: A
A11: SKU00030 | B11: 450 | C11: A
A12: SKU00035 | B12: 448 | C12: A
A13: SKU00025 | B13: 439 | C13: A
... A101: SKU00048 | B101: 61 | C101: C

Sheet STOCK_ACTUAL
A1: UBICACIÓN | B1: SKU | C1: MARCA | D1: FAMILIA | E1: ZONA_ACTUAL | F1: VOLUMEN_M3 | G1: PESO_KG
A2: UB00001 | B2: SKU00001 | C2: Marca A | D2: Filtros | E2: 2. PISO | F2: 0.21854305 | G2: 2.0557447
A3: UB00002 | B3: SKU00002 | C3: Marca B | D3: Lubricantes | E3: 1. LLANTAS | F3: 0.47782144 | G3: 32.002315
A4: UB00003 | B4: SKU00003 | C4: Marca C | D4: Pastillas | E4: 1. LLANTAS | F4: 0.37939727 | G4: 16.060621 | I4: =SUMIF(E2:E101,"*2. PISO*",F2:F101) -> 4.2841488
A5: UB00004 | B5: SKU00004 | C5: Marca D | D5: Correas | E5: 7. MEZANNINE | F5: 0.31939632 | G5: 25.674249 | I5: =COUNTIF(E2:E101,"*2. PISO*") -> 27
A6: UB00005 | B6: SKU00005 | C6: Marca E | D6: Soportes | E6: 2. PISO | F6: 0.12020839 | G6: 45.42454
A7: UB00006 | B7: SKU00006 | C7: Marca A | D7: Filtros | E7: 2. PISO | F7: 0.12019753 | G7: 12.839965
A8: UB00007 | B8: SKU00007 | C8: Marca B | D8: Lubricantes | E8: 1. LLANTAS | F8: 0.076137625 | G8: 20.813955
A9: UB00008 | B9: SKU00008 | C9: Marca C | D9: Pastillas | E9: 8. CLUSTER | F9: 0.43977927 | G9: 37.899781
A10: UB00009 | B10: SKU00009 | C10: Marca D | D10: Correas | E10: 4. RACK BALDA | F10: 0.32050176 | G10: 11.825509
A11: UB00010 | B11: SKU00010 | C11: Marca E | D11: Soportes | E11: 5. RACK SIMPLE | F11: 0.36863266 | G11: 4.3105055
A12: UB00011 | B12: SKU00011 | C12: Marca A | D12: Filtros | E12: 7. MEZANNINE | F12: 0.059263022 | G12: 14.842697
A13: UB00012 | B13: SKU00012 | C13: Marca B | D13: Lubricantes | E13: 7. MEZANNINE | F13: 0.48645943 | G13: 8.4804537
A14: UB00013 | B14: SKU00013 | C14: Marca C | D14: Pastillas | E14: 5. RACK SIMPLE | F14: 0.42459919 | G14: 46.520034
A15: UB00014 | B15: SKU00014 | C15: Marca D | D15: Correas | E15: 2. PISO | F15: 0.1455526 | G15: 40.501959
A16: UB00015 | B16: SKU00015 | C16: Marca E | D16: Soportes | E16: 2. PISO | F16: 0.13182124 | G16: 31.853486
A17: UB00016 | B17: SKU00016 | C17: Marca A | D17: Filtros | E17: 2. PISO | F17: 0.13253203 | G17: 43.637299
... A101: UB00100 | B101: SKU00100 | C101: Marca E | D101: Soportes | E101: 2. PISO | F101: 0.098551142 | G101: 39.10384

Sheet LAYOUT_CD
A1: ZONA | B1: DISTANCIA_METROS | C1: TIEMPO_MINUTOS | D1: CAPACIDAD_M3_MAX
A2: 2. PISO | B2: 10 | C2: 1.6 | D2: 500
A3: 10. UBICACIÓN RECIBO | B3: 15 | C3: 2.01 | D3: 200
A4: 8. CLUSTER | B4: 50 | C4: 4.01 | D4: 300
A5: 4. RACK BALDA | B5: 60 | C5: 4.82 | D5: 250
A6: 5. RACK SIMPLE | B6: 65 | C6: 5.63 | D6: 280
A7: 6. RACK COLGANTES | B7: 45 | C7: 3.61 | D7: 180
A8: 1. LLANTAS | B8: 100 | C8: 8.04 | D8: 400
A9: 7. MEZANNINE | B9: 80 | C9: 6.42 | D9: 350
A10: 14. LATERALES | B10: 70 | C10: 5.63 | D10: 220

Sheet OCUPACION_POR_ZONA
A1: ZONA | B1: CAPACIDAD_MAX_M3 | C1: VOLUMEN_USADO_M3 | D1: VOLUMEN_DISPONIBLE_M3 | E1: PORCENTAJE_USO_%
A2: 2. PISO | B2: 500 | C2: 4.2841488 | D2: 495.71585 | E2: 0.85682976
A3: 10. UBICACIÓN RECIBO | B3: 200 | C3: 1.1248459 | D3: 198.87515 | E3: 0.56242297
A4: 8. CLUSTER | B4: 300 | C4: 2.8136089 | D4: 297.18639 | E4: 0.93786964
A5: 4. RACK BALDA | B5: 250 | C5: 4.4088403 | D5: 245.59116 | E5: 1.7635361
A6: 5. RACK SIMPLE | B6: 280 | C6: 5.2561618 | D6: 274.74384 | E6: 1.8772006
A7: 6. RACK COLGANTES | B7: 180 | C7: 1.6933487 | D7: 178.30665 | E7: 0.94074926
A8: 1. LLANTAS | B8: 400 | C8: 3.7767 | D8: 396.2233 | E8: 0.94417501
A9: 7. MEZANNINE | B9: 350 | C9: 2.800479 | D9: 347.19952 | E9: 0.80013687
A10: 14. LATERALES | B10: 220 | C10: 0 | D10: 220 | E10: 0

Sheet PEDIDOS ACTUAL
A1: PEDIDO_ID | B1: LINEA | C1: SKU | D1: CANTIDAD | E1: ZONA_ACTUAL | F1: TIEMPO_HOY_MIN
A2: 1000 | B2: 1 | C2: SKU00093 | D2: 4 | E2: 1. LLANTAS | F2: 8.37
A3: 1000 | B3: 2 | C3: SKU00032 | D3: 7 | E3: 2. PISO | F3: 1.67
A4: 1000 | B4: 3 | C4: SKU00007 | D4: 6 | E4: 1. LLANTAS | F4: 8.37
A5: 1001 | B5: 1 | C5: SKU00020 | D5: 1 | E5: 2. PISO | F5: 1.67
A6: 1001 | B6: 2 | C6: SKU00022 | D6: 5 | E6: 10. UBICACIÓN RECIBO | F6: 2.09
A7: 1001 | B7: 3 | C7: SKU00076 | D7: 4 | E7: 8. CLUSTER | F7: 4.18
A8: 1002 | B8: 1 | C8: SKU00052 | D8: 7 | E8: 5. RACK SIMPLE | F8: 5.86
A9: 1002 | B9: 2 | C9: SKU00071 | D9: 1 | E9: 4. RACK BALDA | F9: 5.02
A10: 1002 | B10: 3 | C10: SKU00055 | D10: 6 | E10: 5. RACK SIMPLE | F10: 5.86
A11: 1002 | B11: 4 | C11: SKU00043 | D11: 1 | E11: 7. MEZANNINE | F11: 6.69
A12: 1002 | B12: 5 | C12: SKU00007 | D12: 2 | E12: 1. LLANTAS | F12: 8.37
A13: 1003 | B13: 1 | C13: SKU00094 | D13: 3 | E13: 1. LLANTAS | F13: 8.37
... A1501: 1434 | B1501: 1 | C1501: SKU00099 | D1501: 7 | E1501: 2. PISO | F1501: 1.67

Sheet CONSTRUYE_TU_SLOTTING
A1: SKU | B1: MARCA | C1: FAMILIA | D1: ROT_6M | E1: VOL_M3 | F1: PESO_KG | G1: ZONA_ACTUAL | H1: TIEMPO_HOY_MIN | I1: MI_LOGICA | J1: ZONA_NUEVA | K1: TIEMPO_NUEVO_MIN | L1: JUSTIFICACION
A2: SKU00001 | B2: Marca A | C2: Filtros
A3: SKU00002 | B3: Marca B | C3: Lubricantes
A4: SKU00003 | B4: Marca C | C4: Pastillas
A5: SKU00004 | B5: Marca D | C5: Correas
A6: SKU00005 | B6: Marca E | C6: Soportes
A7: SKU00006 | B7: Marca A | C7: Filtros
A8: SKU00007 | B8: Marca B | C8: Lubricantes
A9: SKU00008 | B9: Marca C | C9: Pastillas
A10: SKU00009 | B10: Marca D | C10: Correas
A11: SKU00010 | B11: Marca E | C11: Soportes
A12: SKU00011 | B12: Marca A | C12: Filtros
A13: SKU00012 | B13: Marca B | C13: Lubricantes
... A101: SKU00100 | B101: Marca E | C101: Soportes

Sheet ANALYTICS_BASE
A1: BASE ANALÍTICA CONSOLIDADA — CD ALDEAS / INCHCAPE PERÚ | P1: 4 | Q1: Umbral de zona lejana (min de acceso) — supuesto ajustable
A2: Muestra académica 100 SKU. Todas las celdas de esta hoja son fórmulas que referencian las hojas fuente originales.
A4: SKU | B4: MARCA | C4: FAMILIA | D4: ROTACIÓN 6M | E4: ABC | F4: ZONA ACTUAL | G4: TIEMPO ACCESO (MIN) | H4: DISTANCIA (M) | I4: VOLUMEN M3 | J4: PESO KG | K4: MIN-PICK ANUALIZ. (ROT×TIEMPO) | L4: ZONA LEJANA (>4 MIN) | M4: CANDIDATO RESLOTTING | P4: T1 — DISTRIBUCIÓN ABC | Q4: SKU | R4: % SKU | S4: ROTACIÓN TOTAL | T4: % ROTACIÓN
A5: =STOCK_ACTUAL!B2 -> SKU00001 | B5: =STOCK_ACTUAL!C2 -> Marca A | C5: =STOCK_ACTUAL!D2 -> Filtros | D5: =_xlfn.XLOOKUP($A5,ROTACIÓN!$A$2:$A$101,ROTACIÓN!$B$2:$B$101) -> 422 | E5: =_xlfn.XLOOKUP($A5,ROTACIÓN!$A$2:$A$101,ROTACIÓN!$C$2:$C$101) -> A | F5: =STOCK_ACTUAL!E2 -> 2. PISO | G5: =_xlfn.XLOOKUP($F5,LAYOUT_CD!$A$2:$A$10,LAYOUT_CD!$C$2:$C$10) -> 1.6 | H5: =_xlfn.XLOOKUP($F5,LAYOUT_CD!$A$2:$A$10,LAYOUT_CD!$B$2:$B$10) -> 10 | I5: =STOCK_ACTUAL!F2 -> 0.21854305 | J5: =STOCK_ACTUAL!G2 -> 2.0557447 | K5: =$D5*$G5 -> 675.2 | L5: =IF($G5>$P$1,"SÍ","NO") -> NO | M5: =IF(AND($E5="A",$L5="SÍ"),"SÍ","NO") -> NO | P5: Clase A | Q5: =COUNTIF($E$5:$E$104,"A") -> 39 | R5: =Q5/$Q$8 -> 0.39 | S5: =SUMIF($E$5:$E$104,"A",$D$5:$D$104) -> 16399 | T5: =S5/$S$8 -> 0.55048674
A6: =STOCK_ACTUAL!B3 -> SKU00002 | B6: =STOCK_ACTUAL!C3 -> Marca B | C6: =STOCK_ACTUAL!D3 -> Lubricantes | D6: =_xlfn.XLOOKUP($A6,ROTACIÓN!$A$2:$A$101,ROTACIÓN!$B$2:$B$101) -> 236 | E6: =_xlfn.XLOOKUP($A6,ROTACIÓN!$A$2:$A$101,ROTACIÓN!$C$2:$C$101) -> B | F6: =STOCK_ACTUAL!E3 -> 1. LLANTAS | G6: =_xlfn.XLOOKUP($F6,LAYOUT_CD!$A$2:$A$10,LAYOUT_CD!$C$2:$C$10) -> 8.04 | H6: =_xlfn.XLOOKUP($F6,LAYOUT_CD!$A$2:$A$10,LAYOUT_CD!$B$2:$B$10) -> 100 | I6: =STOCK_ACTUAL!F3 -> 0.47782144 | J6: =STOCK_ACTUAL!G3 -> 32.002315 | K6: =$D6*$G6 -> 1897.44 | L6: =IF($G6>$P$1,"SÍ","NO") -> SÍ | M6: =IF(AND($E6="A",$L6="SÍ"),"SÍ","NO") -> NO | P6: Clase B | Q6: =COUNTIF($E$5:$E$104,"B") -> 35 | R6: =Q6/$Q$8 -> 0.35 | S6: =SUMIF($E$5:$E$104,"B",$D$5:$D$104) -> 9735 | T6: =S6/$S$8 -> 0.32678751
A7: =STOCK_ACTUAL!B4 -> SKU00003 | B7: =STOCK_ACTUAL!C4 -> Marca C | C7: =STOCK_ACTUAL!D4 -> Pastillas | D7: =_xlfn.XLOOKUP($A7,ROTACIÓN!$A$2:$A$101,ROTACIÓN!$B$2:$B$101) -> 231 | E7: =_xlfn.XLOOKUP($A7,ROTACIÓN!$A$2:$A$101,ROTACIÓN!$C$2:$C$101) -> B | F7: =STOCK_ACTUAL!E4 -> 1. LLANTAS | G7: =_xlfn.XLOOKUP($F7,LAYOUT_CD!$A$2:$A$10,LAYOUT_CD!$C$2:$C$10) -> 8.04 | H7: =_xlfn.XLOOKUP($F7,LAYOUT_CD!$A$2:$A$10,LAYOUT_CD!$B$2:$B$10) -> 100 | I7: =STOCK_ACTUAL!F4 -> 0.37939727 | J7: =STOCK_ACTUAL!G4 -> 16.060621 | K7: =$D7*$G7 -> 1857.24 | L7: =IF($G7>$P$1,"SÍ","NO") -> SÍ | M7: =IF(AND($E7="A",$L7="SÍ"),"SÍ","NO") -> NO | P7: Clase C | Q7: =COUNTIF($E$5:$E$104,"C") -> 26 | R7: =Q7/$Q$8 -> 0.26 | S7: =SUMIF($E$5:$E$104,"C",$D$5:$D$104) -> 3656 | T7: =S7/$S$8 -> 0.12272575
A8: =STOCK_ACTUAL!B5 -> SKU00004 | B8: =STOCK_ACTUAL!C5 -> Marca D | C8: =STOCK_ACTUAL!D5 -> Correas | D8: =_xlfn.XLOOKUP($A8,ROTACIÓN!$A$2:$A$101,ROTACIÓN!$B$2:$B$101) -> 208 | E8: =_xlfn.XLOOKUP($A8,ROTACIÓN!$A$2:$A$101,ROTACIÓN!$C$2:$C$101) -> B | F8: =STOCK_ACTUAL!E5 -> 7. MEZANNINE | G8: =_xlfn.XLOOKUP($F8,LAYOUT_CD!$A$2:$A$10,LAYOUT_CD!$C$2:$C$10) -> 6.42 | H8: =_xlfn.XLOOKUP($F8,LAYOUT_CD!$A$2:$A$10,LAYOUT_CD!$B$2:$B$10) -> 80 | I8: =STOCK_ACTUAL!F5 -> 0.31939632 | J8: =STOCK_ACTUAL!G5 -> 25.674249 | K8: =$D8*$G8 -> 1335.36 | L8: =IF($G8>$P$1,"SÍ","NO") -> SÍ | M8: =IF(AND($E8="A",$L8="SÍ"),"SÍ","NO") -> NO | P8: TOTAL | Q8: =SUM(Q5:Q7) -> 100 | R8: =SUM(R5:R7) -> 1 | S8: =SUM(S5:S7) -> 29790 | T8: =SUM(T5:T7) -> 1
A9: =STOCK_ACTUAL!B6 -> SKU00005 | B9: =STOCK_ACTUAL!C6 -> Marca E | C9: =STOCK_ACTUAL!D6 -> Soportes | D9: =_xlfn.XLOOKUP($A9,ROTACIÓN!$A$2:$A$101,ROTACIÓN!$B$2:$B$101) -> 465 | E9: =_xlfn.XLOOKUP($A9,ROTACIÓN!$A$2:$A$101,ROTACIÓN!$C$2:$C$101) -> A | F9: =STOCK_ACTUAL!E6 -> 2. PISO | G9: =_xlfn.XLOOKUP($F9,LAYOUT_CD!$A$2:$A$10,LAYOUT_CD!$C$2:$C$10) -> 1.6 | H9: =_xlfn.XLOOKUP($F9,LAYOUT_CD!$A$2:$A$10,LAYOUT_CD!$B$2:$B$10) -> 10 | I9: =STOCK_ACTUAL!F6 -> 0.12020839 | J9: =STOCK_ACTUAL!G6 -> 45.42454 | K9: =$D9*$G9 -> 744 | L9: =IF($G9>$P$1,"SÍ","NO") -> NO | M9: =IF(AND($E9="A",$L9="SÍ"),"SÍ","NO") -> NO
A10: =STOCK_ACTUAL!B7 -> SKU00006 | B10: =STOCK_ACTUAL!C7 -> Marca A | C10: =STOCK_ACTUAL!D7 -> Filtros | D10: =_xlfn.XLOOKUP($A10,ROTACIÓN!$A$2:$A$101,ROTACIÓN!$B$2:$B$101) -> 161 | E10: =_xlfn.XLOOKUP($A10,ROTACIÓN!$A$2:$A$101,ROTACIÓN!$C$2:$C$101) -> C | F10: =STOCK_ACTUAL!E7 -> 2. PISO | G10: =_xlfn.XLOOKUP($F10,LAYOUT_CD!$A$2:$A$10,LAYOUT_CD!$C$2:$C$10) -> 1.6 | H10: =_xlfn.XLOOKUP($F10,LAYOUT_CD!$A$2:$A$10,LAYOUT_CD!$B$2:$B$10) -> 10 | I10: =STOCK_ACTUAL!F7 -> 0.12019753 | J10: =STOCK_ACTUAL!G7 -> 12.839965 | K10: =$D10*$G10 -> 257.6 | L10: =IF($G10>$P$1,"SÍ","NO") -> NO | M10: =IF(AND($E10="A",$L10="SÍ"),"SÍ","NO") -> NO
A11: =STOCK_ACTUAL!B8 -> SKU00007 | B11: =STOCK_ACTUAL!C8 -> Marca B | C11: =STOCK_ACTUAL!D8 -> Lubricantes | D11: =_xlfn.XLOOKUP($A11,ROTACIÓN!$A$2:$A$101,ROTACIÓN!$B$2:$B$101) -> 102 | E11: =_xlfn.XLOOKUP($A11,ROTACIÓN!$A$2:$A$101,ROTACIÓN!$C$2:$C$101) -> C | F11: =STOCK_ACTUAL!E8 -> 1. LLANTAS | G11: =_xlfn.XLOOKUP($F11,LAYOUT_CD!$A$2:$A$10,LAYOUT_CD!$C$2:$C$10) -> 8.04 | H11: =_xlfn.XLOOKUP($F11,LAYOUT_CD!$A$2:$A$10,LAYOUT_CD!$B$2:$B$10) -> 100 | I11: =STOCK_ACTUAL!F8 -> 0.076137625 | J11: =STOCK_ACTUAL!G8 -> 20.813955 | K11: =$D11*$G11 -> 820.08 | L11: =IF($G11>$P$1,"SÍ","NO") -> SÍ | M11: =IF(AND($E11="A",$L11="SÍ"),"SÍ","NO") -> NO | P11: T2 — ROTACIÓN PROMEDIO POR FAMILIA (ranking desc.) | Q11: ROT. PROM. | R11: ROT. TOTAL | S11: N° SKU | T11: N° SKU CLASE A
A12: =STOCK_ACTUAL!B9 -> SKU00008 | B12: =STOCK_ACTUAL!C9 -> Marca C | C12: =STOCK_ACTUAL!D9 -> Pastillas | D12: =_xlfn.XLOOKUP($A12,ROTACIÓN!$A$2:$A$101,ROTACIÓN!$B$2:$B$101) -> 236 | E12: =_xlfn.XLOOKUP($A12,ROTACIÓN!$A$2:$A$101,ROTACIÓN!$C$2:$C$101) -> B | F12: =STOCK_ACTUAL!E9 -> 8. CLUSTER | G12: =_xlfn.XLOOKUP($F12,LAYOUT_CD!$A$2:$A$10,LAYOUT_CD!$C$2:$C$10) -> 4.01 | H12: =_xlfn.XLOOKUP($F12,LAYOUT_CD!$A$2:$A$10,LAYOUT_CD!$B$2:$B$10) -> 50 | I12: =STOCK_ACTUAL!F9 -> 0.43977927 | J12: =STOCK_ACTUAL!G9 -> 37.899781 | K12: =$D12*$G12 -> 946.36 | L12: =IF($G12>$P$1,"SÍ","NO") -> SÍ | M12: =IF(AND($E12="A",$L12="SÍ"),"SÍ","NO") -> NO | P12: Soportes | Q12: =AVERAGEIF($C$5:$C$104,$P12,$D$5:$D$104) -> 352.15 | R12: =SUMIF($C$5:$C$104,$P12,$D$5:$D$104) -> 7043 | S12: =COUNTIF($C$5:$C$104,$P12) -> 20 | T12: =COUNTIFS($C$5:$C$104,$P12,$E$5:$E$104,"A") -> 12
A13: =STOCK_ACTUAL!B10 -> SKU00009 | B13: =STOCK_ACTUAL!C10 -> Marca D | C13: =STOCK_ACTUAL!D10 -> Correas | D13: =_xlfn.XLOOKUP($A13,ROTACIÓN!$A$2:$A$101,ROTACIÓN!$B$2:$B$101) -> 432 | E13: =_xlfn.XLOOKUP($A13,ROTACIÓN!$A$2:$A$101,ROTACIÓN!$C$2:$C$101) -> A | F13: =STOCK_ACTUAL!E10 -> 4. RACK BALDA | G13: =_xlfn.XLOOKUP($F13,LAYOUT_CD!$A$2:$A$10,LAYOUT_CD!$C$2:$C$10) -> 4.82 | H13: =_xlfn.XLOOKUP($F13,LAYOUT_CD!$A$2:$A$10,LAYOUT_CD!$B$2:$B$10) -> 60 | I13: =STOCK_ACTUAL!F10 -> 0.32050176 | J13: =STOCK_ACTUAL!G10 -> 11.825509 | K13: =$D13*$G13 -> 2082.24 | L13: =IF($G13>$P$1,"SÍ","NO") -> SÍ | M13: =IF(AND($E13="A",$L13="SÍ"),"SÍ","NO") -> SÍ | P13: Correas | Q13: =AVERAGEIF($C$5:$C$104,$P13,$D$5:$D$104) -> 338.25 | R13: =SUMIF($C$5:$C$104,$P13,$D$5:$D$104) -> 6765 | S13: =COUNTIF($C$5:$C$104,$P13) -> 20 | T13: =COUNTIFS($C$5:$C$104,$P13,$E$5:$E$104,"A") -> 10
A14: =STOCK_ACTUAL!B11 -> SKU00010 | B14: =STOCK_ACTUAL!C11 -> Marca E | C14: =STOCK_ACTUAL!D11 -> Soportes | D14: =_xlfn.XLOOKUP($A14,ROTACIÓN!$A$2:$A$101,ROTACIÓN!$B$2:$B$101) -> 316 | E14: =_xlfn.XLOOKUP($A14,ROTACIÓN!$A$2:$A$101,ROTACIÓN!$C$2:$C$101) -> B | F14: =STOCK_ACTUAL!E11 -> 5. RACK SIMPLE | G14: =_xlfn.XLOOKUP($F14,LAYOUT_CD!$A$2:$A$10,LAYOUT_CD!$C$2:$C$10) -> 5.63 | H14: =_xlfn.XLOOKUP($F14,LAYOUT_CD!$A$2:$A$10,LAYOUT_CD!$B$2:$B$10) -> 65 | I14: =STOCK_ACTUAL!F11 -> 0.36863266 | J14: =STOCK_ACTUAL!G11 -> 4.3105055 | K14: =$D14*$G14 -> 1779.08 | L14: =IF($G14>$P$1,"SÍ","NO") -> SÍ | M14: =IF(AND($E14="A",$L14="SÍ"),"SÍ","NO") -> NO | P14: Filtros | Q14: =AVERAGEIF($C$5:$C$104,$P14,$D$5:$D$104) -> 281.05 | R14: =SUMIF($C$5:$C$104,$P14,$D$5:$D$104) -> 5621 | S14: =COUNTIF($C$5:$C$104,$P14) -> 20 | T14: =COUNTIFS($C$5:$C$104,$P14,$E$5:$E$104,"A") -> 6
A15: =STOCK_ACTUAL!B12 -> SKU00011 | B15: =STOCK_ACTUAL!C12 -> Marca A | C15: =STOCK_ACTUAL!D12 -> Filtros | D15: =_xlfn.XLOOKUP($A15,ROTACIÓN!$A$2:$A$101,ROTACIÓN!$B$2:$B$101) -> 219 | E15: =_xlfn.XLOOKUP($A15,ROTACIÓN!$A$2:$A$101,ROTACIÓN!$C$2:$C$101) -> B | F15: =STOCK_ACTUAL!E12 -> 7. MEZANNINE | G15: =_xlfn.XLOOKUP($F15,LAYOUT_CD!$A$2:$A$10,LAYOUT_CD!$C$2:$C$10) -> 6.42 | H15: =_xlfn.XLOOKUP($F15,LAYOUT_CD!$A$2:$A$10,LAYOUT_CD!$B$2:$B$10) -> 80 | I15: =STOCK_ACTUAL!F12 -> 0.059263022 | J15: =STOCK_ACTUAL!G12 -> 14.842697 | K15: =$D15*$G15 -> 1405.98 | L15: =IF($G15>$P$1,"SÍ","NO") -> SÍ | M15: =IF(AND($E15="A",$L15="SÍ"),"SÍ","NO") -> NO | P15: Pastillas | Q15: =AVERAGEIF($C$5:$C$104,$P15,$D$5:$D$104) -> 267.75 | R15: =SUMIF($C$5:$C$104,$P15,$D$5:$D$104) -> 5355 | S15: =COUNTIF($C$5:$C$104,$P15) -> 20 | T15: =COUNTIFS($C$5:$C$104,$P15,$E$5:$E$104,"A") -> 7
A16: =STOCK_ACTUAL!B13 -> SKU00012 | B16: =STOCK_ACTUAL!C13 -> Marca B | C16: =STOCK_ACTUAL!D13 -> Lubricantes | D16: =_xlfn.XLOOKUP($A16,ROTACIÓN!$A$2:$A$101,ROTACIÓN!$B$2:$B$101) -> 150 | E16: =_xlfn.XLOOKUP($A16,ROTACIÓN!$A$2:$A$101,ROTACIÓN!$C$2:$C$101) -> C | F16: =STOCK_ACTUAL!E13 -> 7. MEZANNINE | G16: =_xlfn.XLOOKUP($F16,LAYOUT_CD!$A$2:$A$10,LAYOUT_CD!$C$2:$C$10) -> 6.42 | H16: =_xlfn.XLOOKUP($F16,LAYOUT_CD!$A$2:$A$10,LAYOUT_CD!$B$2:$B$10) -> 80 | I16: =STOCK_ACTUAL!F13 -> 0.48645943 | J16: =STOCK_ACTUAL!G13 -> 8.4804537 | K16: =$D16*$G16 -> 963 | L16: =IF($G16>$P$1,"SÍ","NO") -> SÍ | M16: =IF(AND($E16="A",$L16="SÍ"),"SÍ","NO") -> NO | P16: Lubricantes | Q16: =AVERAGEIF($C$5:$C$104,$P16,$D$5:$D$104) -> 250.3 | R16: =SUMIF($C$5:$C$104,$P16,$D$5:$D$104) -> 5006 | S16: =COUNTIF($C$5:$C$104,$P16) -> 20 | T16: =COUNTIFS($C$5:$C$104,$P16,$E$5:$E$104,"A") -> 4
A17: =STOCK_ACTUAL!B14 -> SKU00013 | B17: =STOCK_ACTUAL!C14 -> Marca C | C17: =STOCK_ACTUAL!D14 -> Pastillas | D17: =_xlfn.XLOOKUP($A17,ROTACIÓN!$A$2:$A$101,ROTACIÓN!$B$2:$B$101) -> 398 | E17: =_xlfn.XLOOKUP($A17,ROTACIÓN!$A$2:$A$101,ROTACIÓN!$C$2:$C$101) -> A | F17: =STOCK_ACTUAL!E14 -> 5. RACK SIMPLE | G17: =_xlfn.XLOOKUP($F17,LAYOUT_CD!$A$2:$A$10,LAYOUT_CD!$C$2:$C$10) -> 5.63 | H17: =_xlfn.XLOOKUP($F17,LAYOUT_CD!$A$2:$A$10,LAYOUT_CD!$B$2:$B$10) -> 65 | I17: =STOCK_ACTUAL!F14 -> 0.42459919 | J17: =STOCK_ACTUAL!G14 -> 46.520034 | K17: =$D17*$G17 -> 2240.74 | L17: =IF($G17>$P$1,"SÍ","NO") -> SÍ | M17: =IF(AND($E17="A",$L17="SÍ"),"SÍ","NO") -> SÍ
A18: =STOCK_ACTUAL!B15 -> SKU00014 | B18: =STOCK_ACTUAL!C15 -> Marca D | C18: =STOCK_ACTUAL!D15 -> Correas | D18: =_xlfn.XLOOKUP($A18,ROTACIÓN!$A$2:$A$101,ROTACIÓN!$B$2:$B$101) -> 352 | E18: =_xlfn.XLOOKUP($A18,ROTACIÓN!$A$2:$A$101,ROTACIÓN!$C$2:$C$101) -> A | F18: =STOCK_ACTUAL!E15 -> 2. PISO | G18: =_xlfn.XLOOKUP($F18,LAYOUT_CD!$A$2:$A$10,LAYOUT_CD!$C$2:$C$10) -> 1.6 | H18: =_xlfn.XLOOKUP($F18,LAYOUT_CD!$A$2:$A$10,LAYOUT_CD!$B$2:$B$10) -> 10 | I18: =STOCK_ACTUAL!F15 -> 0.1455526 | J18: =STOCK_ACTUAL!G15 -> 40.501959 | K18: =$D18*$G18 -> 563.2 | L18: =IF($G18>$P$1,"SÍ","NO") -> NO | M18: =IF(AND($E18="A",$L18="SÍ"),"SÍ","NO") -> NO
A19: =STOCK_ACTUAL!B16 -> SKU00015 | B19: =STOCK_ACTUAL!C16 -> Marca E | C19: =STOCK_ACTUAL!D16 -> Soportes | D19: =_xlfn.XLOOKUP($A19,ROTACIÓN!$A$2:$A$101,ROTACIÓN!$B$2:$B$101) -> 401 | E19: =_xlfn.XLOOKUP($A19,ROTACIÓN!$A$2:$A$101,ROTACIÓN!$C$2:$C$101) -> A | F19: =STOCK_ACTUAL!E16 -> 2. PISO | G19: =_xlfn.XLOOKUP($F19,LAYOUT_CD!$A$2:$A$10,LAYOUT_CD!$C$2:$C$10) -> 1.6 | H19: =_xlfn.XLOOKUP($F19,LAYOUT_CD!$A$2:$A$10,LAYOUT_CD!$B$2:$B$10) -> 10 | I19: =STOCK_ACTUAL!F16 -> 0.13182124 | J19: =STOCK_ACTUAL!G16 -> 31.853486 | K19: =$D19*$G19 -> 641.6 | L19: =IF($G19>$P$1,"SÍ","NO") -> NO | M19: =IF(AND($E19="A",$L19="SÍ"),"SÍ","NO") -> NO | P19: T3-T7 — PANEL CONSOLIDADO POR ZONA | Q19: N° SKU | R19: ROT. PROM. | S19: TIEMPO ACCESO (MIN) | T19: DIST. (M) | U19: VOL. USADO M3 | V19: CAPACIDAD M3 | W19: % USO | X19: SKU A | Y19: SKU B | Z19: SKU C | AA19: MIN-PICK TOTAL
A20: =STOCK_ACTUAL!B17 -> SKU00016 | B20: =STOCK_ACTUAL!C17 -> Marca A | C20: =STOCK_ACTUAL!D17 -> Filtros | D20: =_xlfn.XLOOKUP($A20,ROTACIÓN!$A$2:$A$101,ROTACIÓN!$B$2:$B$101) -> 302 | E20: =_xlfn.XLOOKUP($A20,ROTACIÓN!$A$2:$A$101,ROTACIÓN!$C$2:$C$101) -> B | F20: =STOCK_ACTUAL!E17 -> 2. PISO | G20: =_xlfn.XLOOKUP($F20,LAYOUT_CD!$A$2:$A$10,LAYOUT_CD!$C$2:$C$10) -> 1.6 | H20: =_xlfn.XLOOKUP($F20,LAYOUT_CD!$A$2:$A$10,LAYOUT_CD!$B$2:$B$10) -> 10 | I20: =STOCK_ACTUAL!F17 -> 0.13253203 | J20: =STOCK_ACTUAL!G17 -> 43.637299 | K20: =$D20*$G20 -> 483.2 | L20: =IF($G20>$P$1,"SÍ","NO") -> NO | M20: =IF(AND($E20="A",$L20="SÍ"),"SÍ","NO") -> NO | P20: =LAYOUT_CD!A2 -> 2. PISO | Q20: =COUNTIF($F$5:$F$104,$P20) -> 27 | R20: =IFERROR(AVERAGEIF($F$5:$F$104,$P20,$D$5:$D$104),0) -> 305.40741 | S20: =_xlfn.XLOOKUP($P20,LAYOUT_CD!$A$2:$A$10,LAYOUT_CD!$C$2:$C$10) -> 1.6 | T20: =_xlfn.XLOOKUP($P20,LAYOUT_CD!$A$2:$A$10,LAYOUT_CD!$B$2:$B$10) -> 10 | U20: =SUMIF($F$5:$F$104,$P20,$I$5:$I$104) -> 4.2841488 | V20: =_xlfn.XLOOKUP($P20,LAYOUT_CD!$A$2:$A$10,LAYOUT_CD!$D$2:$D$10) -> 500 | W20: =IFERROR($U20/$V20,0) -> 0.0085682976 | X20: =COUNTIFS($F$5:$F$104,$P20,$E$5:$E$104,"A") -> 13 | Y20: =COUNTIFS($F$5:$F$104,$P20,$E$5:$E$104,"B") -> 6 | Z20: =COUNTIFS($F$5:$F$104,$P20,$E$5:$E$104,"C") -> 8 | AA20: =SUMIF($F$5:$F$104,$P20,$K$5:$K$104) -> 13193.6
A21: =STOCK_ACTUAL!B18 -> SKU00017 | B21: =STOCK_ACTUAL!C18 -> Marca B | C21: =STOCK_ACTUAL!D18 -> Lubricantes | D21: =_xlfn.XLOOKUP($A21,ROTACIÓN!$A$2:$A$101,ROTACIÓN!$B$2:$B$101) -> 314 | E21: =_xlfn.XLOOKUP($A21,ROTACIÓN!$A$2:$A$101,ROTACIÓN!$C$2:$C$101) -> B | F21: =STOCK_ACTUAL!E18 -> 2. PISO | G21: =_xlfn.XLOOKUP($F21,LAYOUT_CD!$A$2:$A$10,LAYOUT_CD!$C$2:$C$10) -> 1.6 | H21: =_xlfn.XLOOKUP($F21,LAYOUT_CD!$A$2:$A$10,LAYOUT_CD!$B$2:$B$10) -> 10 | I21: =STOCK_ACTUAL!F18 -> 0.18690901 | J21: =STOCK_ACTUAL!G18 -> 40.281768 | K21: =$D21*$G21 -> 502.4 | L21: =IF($G21>$P$1,"SÍ","NO") -> NO | M21: =IF(AND($E21="A",$L21="SÍ"),"SÍ","NO") -> NO | P21: =LAYOUT_CD!A3 -> 10. UBICACIÓN RECIBO | Q21: =COUNTIF($F$5:$F$104,$P21) -> 8 | R21: =IFERROR(AVERAGEIF($F$5:$F$104,$P21,$D$5:$D$104),0) -> 330.875 | S21: =_xlfn.XLOOKUP($P21,LAYOUT_CD!$A$2:$A$10,LAYOUT_CD!$C$2:$C$10) -> 2.01 | T21: =_xlfn.XLOOKUP($P21,LAYOUT_CD!$A$2:$A$10,LAYOUT_CD!$B$2:$B$10) -> 15 | U21: =SUMIF($F$5:$F$104,$P21,$I$5:$I$104) -> 1.1248459 | V21: =_xlfn.XLOOKUP($P21,LAYOUT_CD!$A$2:$A$10,LAYOUT_CD!$D$2:$D$10) -> 200 | W21: =IFERROR($U21/$V21,0) -> 0.0056242297 | X21: =COUNTIFS($F$5:$F$104,$P21,$E$5:$E$104,"A") -> 4 | Y21: =COUNTIFS($F$5:$F$104,$P21,$E$5:$E$104,"B") -> 2 | Z21: =COUNTIFS($F$5:$F$104,$P21,$E$5:$E$104,"C") -> 2 | AA21: =SUMIF($F$5:$F$104,$P21,$K$5:$K$104) -> 5320.47
A22: =STOCK_ACTUAL!B19 -> SKU00018 | B22: =STOCK_ACTUAL!C19 -> Marca C | C22: =STOCK_ACTUAL!D19 -> Pastillas | D22: =_xlfn.XLOOKUP($A22,ROTACIÓN!$A$2:$A$101,ROTACIÓN!$B$2:$B$101) -> 451 | E22: =_xlfn.XLOOKUP($A22,ROTACIÓN!$A$2:$A$101,ROTACIÓN!$C$2:$C$101) -> A | F22: =STOCK_ACTUAL!E19 -> 2. PISO | G22: =_xlfn.XLOOKUP($F22,LAYOUT_CD!$A$2:$A$10,LAYOUT_CD!$C$2:$C$10) -> 1.6 | H22: =_xlfn.XLOOKUP($F22,LAYOUT_CD!$A$2:$A$10,LAYOUT_CD!$B$2:$B$10) -> 10 | I22: =STOCK_ACTUAL!F19 -> 0.28614039 | J22: =STOCK_ACTUAL!G19 -> 9.7352179 | K22: =$D22*$G22 -> 721.6 | L22: =IF($G22>$P$1,"SÍ","NO") -> NO | M22: =IF(AND($E22="A",$L22="SÍ"),"SÍ","NO") -> NO | P22: =LAYOUT_CD!A4 -> 8. CLUSTER | Q22: =COUNTIF($F$5:$F$104,$P22) -> 7 | R22: =IFERROR(AVERAGEIF($F$5:$F$104,$P22,$D$5:$D$104),0) -> 291.71429 | S22: =_xlfn.XLOOKUP($P22,LAYOUT_CD!$A$2:$A$10,LAYOUT_CD!$C$2:$C$10) -> 4.01 | T22: =_xlfn.XLOOKUP($P22,LAYOUT_CD!$A$2:$A$10,LAYOUT_CD!$B$2:$B$10) -> 50 | U22: =SUMIF($F$5:$F$104,$P22,$I$5:$I$104) -> 2.8136089 | V22: =_xlfn.XLOOKUP($P22,LAYOUT_CD!$A$2:$A$10,LAYOUT_CD!$D$2:$D$10) -> 300 | W22: =IFERROR($U22/$V22,0) -> 0.0093786964 | X22: =COUNTIFS($F$5:$F$104,$P22,$E$5:$E$104,"A") -> 2 | Y22: =COUNTIFS($F$5:$F$104,$P22,$E$5:$E$104,"B") -> 3 | Z22: =COUNTIFS($F$5:$F$104,$P22,$E$5:$E$104,"C") -> 2 | AA22: =SUMIF($F$5:$F$104,$P22,$K$5:$K$104) -> 8188.42
A23: =STOCK_ACTUAL!B20 -> SKU00019 | B23: =STOCK_ACTUAL!C20 -> Marca D | C23: =STOCK_ACTUAL!D20 -> Correas | D23: =_xlfn.XLOOKUP($A23,ROTACIÓN!$A$2:$A$101,ROTACIÓN!$B$2:$B$101) -> 186 | E23: =_xlfn.XLOOKUP($A23,ROTACIÓN!$A$2:$A$101,ROTACIÓN!$C$2:$C$101) -> C | F23: =STOCK_ACTUAL!E20 -> 5. RACK SIMPLE | G23: =_xlfn.XLOOKUP($F23,LAYOUT_CD!$A$2:$A$10,LAYOUT_CD!$C$2:$C$10) -> 5.63 | H23: =_xlfn.XLOOKUP($F23,LAYOUT_CD!$A$2:$A$10,LAYOUT_CD!$B$2:$B$10) -> 65 | I23: =STOCK_ACTUAL!F20 -> 0.24437526 | J23: =STOCK_ACTUAL!G20 -> 44.68167 | K23: =$D23*$G23 -> 1047.18 | L23: =IF($G23>$P$1,"SÍ","NO") -> SÍ | M23: =IF(AND($E23="A",$L23="SÍ"),"SÍ","NO") -> NO | P23: =LAYOUT_CD!A5 -> 4. RACK BALDA | Q23: =COUNTIF($F$5:$F$104,$P23) -> 12 | R23: =IFERROR(AVERAGEIF($F$5:$F$104,$P23,$D$5:$D$104),0) -> 266.16667 | S23: =_xlfn.XLOOKUP($P23,LAYOUT_CD!$A$2:$A$10,LAYOUT_CD!$C$2:$C$10) -> 4.82 | T23: =_xlfn.XLOOKUP($P23,LAYOUT_CD!$A$2:$A$10,LAYOUT_CD!$B$2:$B$10) -> 60 | U23: =SUMIF($F$5:$F$104,$P23,$I$5:$I$104) -> 4.4088403 | V23: =_xlfn.XLOOKUP($P23,LAYOUT_CD!$A$2:$A$10,LAYOUT_CD!$D$2:$D$10) -> 250 | W23: =IFERROR($U23/$V23,0) -> 0.017635361 | X23: =COUNTIFS($F$5:$F$104,$P23,$E$5:$E$104,"A") -> 5 | Y23: =COUNTIFS($F$5:$F$104,$P23,$E$5:$E$104,"B") -> 2 | Z23: =COUNTIFS($F$5:$F$104,$P23,$E$5:$E$104,"C") -> 5 | AA23: =SUMIF($F$5:$F$104,$P23,$K$5:$K$104) -> 15395.08
A24: =STOCK_ACTUAL!B21 -> SKU00020 | B24: =STOCK_ACTUAL!C21 -> Marca E | C24: =STOCK_ACTUAL!D21 -> Soportes | D24: =_xlfn.XLOOKUP($A24,ROTACIÓN!$A$2:$A$101,ROTACIÓN!$B$2:$B$101) -> 399 | E24: =_xlfn.XLOOKUP($A24,ROTACIÓN!$A$2:$A$101,ROTACIÓN!$C$2:$C$101) -> A | F24: =STOCK_ACTUAL!E21 -> 2. PISO | G24: =_xlfn.XLOOKUP($F24,LAYOUT_CD!$A$2:$A$10,LAYOUT_CD!$C$2:$C$10) -> 1.6 | H24: =_xlfn.XLOOKUP($F24,LAYOUT_CD!$A$2:$A$10,LAYOUT_CD!$B$2:$B$10) -> 10 | I24: =STOCK_ACTUAL!F21 -> 0.18105311 | J24: =STOCK_ACTUAL!G21 -> 27.197441 | K24: =$D24*$G24 -> 638.4 | L24: =IF($G24>$P$1,"SÍ","NO") -> NO | M24: =IF(AND($E24="A",$L24="SÍ"),"SÍ","NO") -> NO | P24: =LAYOUT_CD!A6 -> 5. RACK SIMPLE | Q24: =COUNTIF($F$5:$F$104,$P24) -> 15 | R24: =IFERROR(AVERAGEIF($F$5:$F$104,$P24,$D$5:$D$104),0) -> 318.46667 | S24: =_xlfn.XLOOKUP($P24,LAYOUT_CD!$A$2:$A$10,LAYOUT_CD!$C$2:$C$10) -> 5.63 | T24: =_xlfn.XLOOKUP($P24,LAYOUT_CD!$A$2:$A$10,LAYOUT_CD!$B$2:$B$10) -> 65 | U24: =SUMIF($F$5:$F$104,$P24,$I$5:$I$104) -> 5.2561618 | V24: =_xlfn.XLOOKUP($P24,LAYOUT_CD!$A$2:$A$10,LAYOUT_CD!$D$2:$D$10) -> 280 | W24: =IFERROR($U24/$V24,0) -> 0.018772006 | X24: =COUNTIFS($F$5:$F$104,$P24,$E$5:$E$104,"A") -> 6 | Y24: =COUNTIFS($F$5:$F$104,$P24,$E$5:$E$104,"B") -> 6 | Z24: =COUNTIFS($F$5:$F$104,$P24,$E$5:$E$104,"C") -> 3 | AA24: =SUMIF($F$5:$F$104,$P24,$K$5:$K$104) -> 26894.51
A25: =STOCK_ACTUAL!B22 -> SKU00021 | B25: =STOCK_ACTUAL!C22 -> Marca A | C25: =STOCK_ACTUAL!D22 -> Filtros | D25: =_xlfn.XLOOKUP($A25,ROTACIÓN!$A$2:$A$101,ROTACIÓN!$B$2:$B$101) -> 167 | E25: =_xlfn.XLOOKUP($A25,ROTACIÓN!$A$2:$A$101,ROTACIÓN!$C$2:$C$101) -> C | F25: =STOCK_ACTUAL!E22 -> 5. RACK SIMPLE | G25: =_xlfn.XLOOKUP($F25,LAYOUT_CD!$A$2:$A$10,LAYOUT_CD!$C$2:$C$10) -> 5.63 | H25: =_xlfn.XLOOKUP($F25,LAYOUT_CD!$A$2:$A$10,LAYOUT_CD!$B$2:$B$10) -> 65 | I25: =STOCK_ACTUAL!F22 -> 0.3253338 | J25: =STOCK_ACTUAL!G22 -> 40.468288 | K25: =$D25*$G25 -> 940.21 | L25: =IF($G25>$P$1,"SÍ","NO") -> SÍ | M25: =IF(AND($E25="A",$L25="SÍ"),"SÍ","NO") -> NO | P25: =LAYOUT_CD!A7 -> 6. RACK COLGANTES | Q25: =COUNTIF($F$5:$F$104,$P25) -> 6 | R25: =IFERROR(AVERAGEIF($F$5:$F$104,$P25,$D$5:$D$104),0) -> 272.5 | S25: =_xlfn.XLOOKUP($P25,LAYOUT_CD!$A$2:$A$10,LAYOUT_CD!$C$2:$C$10) -> 3.61 | T25: =_xlfn.XLOOKUP($P25,LAYOUT_CD!$A$2:$A$10,LAYOUT_CD!$B$2:$B$10) -> 45 | U25: =SUMIF($F$5:$F$104,$P25,$I$5:$I$104) -> 1.6933487 | V25: =_xlfn.XLOOKUP($P25,LAYOUT_CD!$A$2:$A$10,LAYOUT_CD!$D$2:$D$10) -> 180 | W25: =IFERROR($U25/$V25,0) -> 0.0094074926 | X25: =COUNTIFS($F$5:$F$104,$P25,$E$5:$E$104,"A") -> 2 | Y25: =COUNTIFS($F$5:$F$104,$P25,$E$5:$E$104,"B") -> 2 | Z25: =COUNTIFS($F$5:$F$104,$P25,$E$5:$E$104,"C") -> 2 | AA25: =SUMIF($F$5:$F$104,$P25,$K$5:$K$104) -> 5902.35
A26: =STOCK_ACTUAL!B23 -> SKU00022 | B26: =STOCK_ACTUAL!C23 -> Marca B | C26: =STOCK_ACTUAL!D23 -> Lubricantes | D26: =_xlfn.XLOOKUP($A26,ROTACIÓN!$A$2:$A$101,ROTACIÓN!$B$2:$B$101) -> 298 | E26: =_xlfn.XLOOKUP($A26,ROTACIÓN!$A$2:$A$101,ROTACIÓN!$C$2:$C$101) -> B | F26: =STOCK_ACTUAL!E23 -> 10. UBICACIÓN RECIBO | G26: =_xlfn.XLOOKUP($F26,LAYOUT_CD!$A$2:$A$10,LAYOUT_CD!$C$2:$C$10) -> 2.01 | H26: =_xlfn.XLOOKUP($F26,LAYOUT_CD!$A$2:$A$10,LAYOUT_CD!$B$2:$B$10) -> 15 | I26: =STOCK_ACTUAL!F23 -> 0.11277224 | J26: =STOCK_ACTUAL!G23 -> 44.856519 | K26: =$D26*$G26 -> 598.98 | L26: =IF($G26>$P$1,"SÍ","NO") -> NO | M26: =IF(AND($E26="A",$L26="SÍ"),"SÍ","NO") -> NO | P26: =LAYOUT_CD!A8 -> 1. LLANTAS | Q26: =COUNTIF($F$5:$F$104,$P26) -> 15 | R26: =IFERROR(AVERAGEIF($F$5:$F$104,$P26,$D$5:$D$104),0) -> 273 | S26: =_xlfn.XLOOKUP($P26,LAYOUT_CD!$A$2:$A$10,LAYOUT_CD!$C$2:$C$10) -> 8.04 | T26: =_xlfn.XLOOKUP($P26,LAYOUT_CD!$A$2:$A$10,LAYOUT_CD!$B$2:$B$10) -> 100 | U26: =SUMIF($F$5:$F$104,$P26,$I$5:$I$104) -> 3.7767 | V26: =_xlfn.XLOOKUP($P26,LAYOUT_CD!$A$2:$A$10,LAYOUT_CD!$D$2:$D$10) -> 400 | W26: =IFERROR($U26/$V26,0) -> 0.0094417501 | X26: =COUNTIFS($F$5:$F$104,$P26,$E$5:$E$104,"A") -> 3 | Y26: =COUNTIFS($F$5:$F$104,$P26,$E$5:$E$104,"B") -> 9 | Z26: =COUNTIFS($F$5:$F$104,$P26,$E$5:$E$104,"C") -> 3 | AA26: =SUMIF($F$5:$F$104,$P26,$K$5:$K$104) -> 32923.8
A27: =STOCK_ACTUAL!B24 -> SKU00023 | B27: =STOCK_ACTUAL!C24 -> Marca C | C27: =STOCK_ACTUAL!D24 -> Pastillas | D27: =_xlfn.XLOOKUP($A27,ROTACIÓN!$A$2:$A$101,ROTACIÓN!$B$2:$B$101) -> 186 | E27: =_xlfn.XLOOKUP($A27,ROTACIÓN!$A$2:$A$101,ROTACIÓN!$C$2:$C$101) -> C | F27: =STOCK_ACTUAL!E24 -> 2. PISO | G27: =_xlfn.XLOOKUP($F27,LAYOUT_CD!$A$2:$A$10,LAYOUT_CD!$C$2:$C$10) -> 1.6 | H27: =_xlfn.XLOOKUP($F27,LAYOUT_CD!$A$2:$A$10,LAYOUT_CD!$B$2:$B$10) -> 10 | I27: =STOCK_ACTUAL!F24 -> 0.18146509 | J27: =STOCK_ACTUAL!G24 -> 16.241172 | K27: =$D27*$G27 -> 297.6 | L27: =IF($G27>$P$1,"SÍ","NO") -> NO | M27: =IF(AND($E27="A",$L27="SÍ"),"SÍ","NO") -> NO | P27: =LAYOUT_CD!A9 -> 7. MEZANNINE | Q27: =COUNTIF($F$5:$F$104,$P27) -> 10 | R27: =IFERROR(AVERAGEIF($F$5:$F$104,$P27,$D$5:$D$104),0) -> 315.4 | S27: =_xlfn.XLOOKUP($P27,LAYOUT_CD!$A$2:$A$10,LAYOUT_CD!$C$2:$C$10) -> 6.42 | T27: =_xlfn.XLOOKUP($P27,LAYOUT_CD!$A$2:$A$10,LAYOUT_CD!$B$2:$B$10) -> 80 | U27: =SUMIF($F$5:$F$104,$P27,$I$5:$I$104) -> 2.800479 | V27: =_xlfn.XLOOKUP($P27,LAYOUT_CD!$A$2:$A$10,LAYOUT_CD!$D$2:$D$10) -> 350 | W27: =IFERROR($U27/$V27,0) -> 0.0080013687 | X27: =COUNTIFS($F$5:$F$104,$P27,$E$5:$E$104,"A") -> 4 | Y27: =COUNTIFS($F$5:$F$104,$P27,$E$5:$E$104,"B") -> 5 | Z27: =COUNTIFS($F$5:$F$104,$P27,$E$5:$E$104,"C") -> 1 | AA27: =SUMIF($F$5:$F$104,$P27,$K$5:$K$104) -> 20248.68
A28: =STOCK_ACTUAL!B25 -> SKU00024 | B28: =STOCK_ACTUAL!C25 -> Marca D | C28: =STOCK_ACTUAL!D25 -> Correas | D28: =_xlfn.XLOOKUP($A28,ROTACIÓN!$A$2:$A$101,ROTACIÓN!$B$2:$B$101) -> 171 | E28: =_xlfn.XLOOKUP($A28,ROTACIÓN!$A$2:$A$101,ROTACIÓN!$C$2:$C$101) -> C | F28: =STOCK_ACTUAL!E25 -> 4. RACK BALDA | G28: =_xlfn.XLOOKUP($F28,LAYOUT_CD!$A$2:$A$10,LAYOUT_CD!$C$2:$C$10) -> 4.82 | H28: =_xlfn.XLOOKUP($F28,LAYOUT_CD!$A$2:$A$10,LAYOUT_CD!$B$2:$B$10) -> 60 | I28: =STOCK_ACTUAL!F25 -> 0.21486283 | J28: =STOCK_ACTUAL!G25 -> 5.9475703 | K28: =$D28*$G28 -> 824.22 | L28: =IF($G28>$P$1,"SÍ","NO") -> SÍ | M28: =IF(AND($E28="A",$L28="SÍ"),"SÍ","NO") -> NO | P28: =LAYOUT_CD!A10 -> 14. LATERALES | Q28: =COUNTIF($F$5:$F$104,$P28) -> 0 | R28: =IFERROR(AVERAGEIF($F$5:$F$104,$P28,$D$5:$D$104),0) -> 0 | S28: =_xlfn.XLOOKUP($P28,LAYOUT_CD!$A$2:$A$10,LAYOUT_CD!$C$2:$C$10) -> 5.63 | T28: =_xlfn.XLOOKUP($P28,LAYOUT_CD!$A$2:$A$10,LAYOUT_CD!$B$2:$B$10) -> 70 | U28: =SUMIF($F$5:$F$104,$P28,$I$5:$I$104) -> 0 | V28: =_xlfn.XLOOKUP($P28,LAYOUT_CD!$A$2:$A$10,LAYOUT_CD!$D$2:$D$10) -> 220 | W28: =IFERROR($U28/$V28,0) -> 0 | X28: =COUNTIFS($F$5:$F$104,$P28,$E$5:$E$104,"A") -> 0 | Y28: =COUNTIFS($F$5:$F$104,$P28,$E$5:$E$104,"B") -> 0 | Z28: =COUNTIFS($F$5:$F$104,$P28,$E$5:$E$104,"C") -> 0 | AA28: =SUMIF($F$5:$F$104,$P28,$K$5:$K$104) -> 0
A29: =STOCK_ACTUAL!B26 -> SKU00025 | B29: =STOCK_ACTUAL!C26 -> Marca E | C29: =STOCK_ACTUAL!D26 -> Soportes | D29: =_xlfn.XLOOKUP($A29,ROTACIÓN!$A$2:$A$101,ROTACIÓN!$B$2:$B$101) -> 439 | E29: =_xlfn.XLOOKUP($A29,ROTACIÓN!$A$2:$A$101,ROTACIÓN!$C$2:$C$101) -> A | F29: =STOCK_ACTUAL!E26 -> 5. RACK SIMPLE | G29: =_xlfn.XLOOKUP($F29,LAYOUT_CD!$A$2:$A$10,LAYOUT_CD!$C$2:$C$10) -> 5.63 | H29: =_xlfn.XLOOKUP($F29,LAYOUT_CD!$A$2:$A$10,LAYOUT_CD!$B$2:$B$10) -> 65 | I29: =STOCK_ACTUAL!F26 -> 0.25523149 | J29: =STOCK_ACTUAL!G26 -> 11.782791 | K29: =$D29*$G29 -> 2471.57 | L29: =IF($G29>$P$1,"SÍ","NO") -> SÍ | M29: =IF(AND($E29="A",$L29="SÍ"),"SÍ","NO") -> SÍ
A30: =STOCK_ACTUAL!B27 -> SKU00026 | B30: =STOCK_ACTUAL!C27 -> Marca A | C30: =STOCK_ACTUAL!D27 -> Filtros | D30: =_xlfn.XLOOKUP($A30,ROTACIÓN!$A$2:$A$101,ROTACIÓN!$B$2:$B$101) -> 484 | E30: =_xlfn.XLOOKUP($A30,ROTACIÓN!$A$2:$A$101,ROTACIÓN!$C$2:$C$101) -> A | F30: =STOCK_ACTUAL!E27 -> 6. RACK COLGANTES | G30: =_xlfn.XLOOKUP($F30,LAYOUT_CD!$A$2:$A$10,LAYOUT_CD!$C$2:$C$10) -> 3.61 | H30: =_xlfn.XLOOKUP($F30,LAYOUT_CD!$A$2:$A$10,LAYOUT_CD!$B$2:$B$10) -> 45 | I30: =STOCK_ACTUAL!F27 -> 0.40332918 | J30: =STOCK_ACTUAL!G27 -> 21.641836 | K30: =$D30*$G30 -> 1747.24 | L30: =IF($G30>$P$1,"SÍ","NO") -> NO | M30: =IF(AND($E30="A",$L30="SÍ"),"SÍ","NO") -> NO
A31: =STOCK_ACTUAL!B28 -> SKU00027 | B31: =STOCK_ACTUAL!C28 -> Marca B | C31: =STOCK_ACTUAL!D28 -> Lubricantes | D31: =_xlfn.XLOOKUP($A31,ROTACIÓN!$A$2:$A$101,ROTACIÓN!$B$2:$B$101) -> 72 | E31: =_xlfn.XLOOKUP($A31,ROTACIÓN!$A$2:$A$101,ROTACIÓN!$C$2:$C$101) -> C | F31: =STOCK_ACTUAL!E28 -> 10. UBICACIÓN RECIBO | G31: =_xlfn.XLOOKUP($F31,LAYOUT_CD!$A$2:$A$10,LAYOUT_CD!$C$2:$C$10) -> 2.01 | H31: =_xlfn.XLOOKUP($F31,LAYOUT_CD!$A$2:$A$10,LAYOUT_CD!$B$2:$B$10) -> 15 | I31: =STOCK_ACTUAL!F28 -> 0.1398532 | J31: =STOCK_ACTUAL!G28 -> 40.991731 | K31: =$D31*$G31 -> 144.72 | L31: =IF($G31>$P$1,"SÍ","NO") -> NO | M31: =IF(AND($E31="A",$L31="SÍ"),"SÍ","NO") -> NO | P31: T8 — TOP 20 SKU POR ROTACIÓN (PARETO) | Q31: ROTACIÓN | R31: % ACUM. DEL MOVIMIENTO TOTAL | S31: ZONA ACTUAL | T31: TIEMPO (MIN)
A32: =STOCK_ACTUAL!B29 -> SKU00028 | B32: =STOCK_ACTUAL!C29 -> Marca C | C32: =STOCK_ACTUAL!D29 -> Pastillas | D32: =_xlfn.XLOOKUP($A32,ROTACIÓN!$A$2:$A$101,ROTACIÓN!$B$2:$B$101) -> 353 | E32: =_xlfn.XLOOKUP($A32,ROTACIÓN!$A$2:$A$101,ROTACIÓN!$C$2:$C$101) -> A | F32: =STOCK_ACTUAL!E29 -> 2. PISO | G32: =_xlfn.XLOOKUP($F32,LAYOUT_CD!$A$2:$A$10,LAYOUT_CD!$C$2:$C$10) -> 1.6 | H32: =_xlfn.XLOOKUP($F32,LAYOUT_CD!$A$2:$A$10,LAYOUT_CD!$B$2:$B$10) -> 10 | I32: =STOCK_ACTUAL!F29 -> 0.2814055 | J32: =STOCK_ACTUAL!G29 -> 43.106164 | K32: =$D32*$G32 -> 564.8 | L32: =IF($G32>$P$1,"SÍ","NO") -> NO | M32: =IF(AND($E32="A",$L32="SÍ"),"SÍ","NO") -> NO | P32: {=INDEX($A$5:$A$104,MATCH(LARGE($D$5:$D$104-ROW($D$5:$D$104)/100000,ROW()-31),$D$5:$D$104-ROW($D$5:$D$104)/100000,0))} -> SKU00085 | Q32: =LARGE($D$5:$D$104,ROW()-31) -> 496 | R32: =SUM($Q$32:$Q32)/$S$8 -> 0.016649883 | S32: =_xlfn.XLOOKUP($P32,$A$5:$A$104,$F$5:$F$104) -> 10. UBICACIÓN RECIBO | T32: =_xlfn.XLOOKUP($P32,$A$5:$A$104,$G$5:$G$104) -> 2.01
A33: =STOCK_ACTUAL!B30 -> SKU00029 | B33: =STOCK_ACTUAL!C30 -> Marca D | C33: =STOCK_ACTUAL!D30 -> Correas | D33: =_xlfn.XLOOKUP($A33,ROTACIÓN!$A$2:$A$101,ROTACIÓN!$B$2:$B$101) -> 419 | E33: =_xlfn.XLOOKUP($A33,ROTACIÓN!$A$2:$A$101,ROTACIÓN!$C$2:$C$101) -> A | F33: =STOCK_ACTUAL!E30 -> 4. RACK BALDA | G33: =_xlfn.XLOOKUP($F33,LAYOUT_CD!$A$2:$A$10,LAYOUT_CD!$C$2:$C$10) -> 4.82 | H33: =_xlfn.XLOOKUP($F33,LAYOUT_CD!$A$2:$A$10,LAYOUT_CD!$B$2:$B$10) -> 60 | I33: =STOCK_ACTUAL!F30 -> 0.31658656 | J33: =STOCK_ACTUAL!G30 -> 0.84413046 | K33: =$D33*$G33 -> 2019.58 | L33: =IF($G33>$P$1,"SÍ","NO") -> SÍ | M33: =IF(AND($E33="A",$L33="SÍ"),"SÍ","NO") -> SÍ | P33: {=INDEX($A$5:$A$104,MATCH(LARGE($D$5:$D$104-ROW($D$5:$D$104)/100000,ROW()-31),$D$5:$D$104-ROW($D$5:$D$104)/100000,0))} -> SKU00078 | Q33: =LARGE($D$5:$D$104,ROW()-31) -> 485 | R33: =SUM($Q$32:$Q33)/$S$8 -> 0.032930514 | S33: =_xlfn.XLOOKUP($P33,$A$5:$A$104,$F$5:$F$104) -> 1. LLANTAS | T33: =_xlfn.XLOOKUP($P33,$A$5:$A$104,$G$5:$G$104) -> 8.04
A34: =STOCK_ACTUAL!B31 -> SKU00030 | B34: =STOCK_ACTUAL!C31 -> Marca E | C34: =STOCK_ACTUAL!D31 -> Soportes | D34: =_xlfn.XLOOKUP($A34,ROTACIÓN!$A$2:$A$101,ROTACIÓN!$B$2:$B$101) -> 450 | E34: =_xlfn.XLOOKUP($A34,ROTACIÓN!$A$2:$A$101,ROTACIÓN!$C$2:$C$101) -> A | F34: =STOCK_ACTUAL!E31 -> 2. PISO | G34: =_xlfn.XLOOKUP($F34,LAYOUT_CD!$A$2:$A$10,LAYOUT_CD!$C$2:$C$10) -> 1.6 | H34: =_xlfn.XLOOKUP($F34,LAYOUT_CD!$A$2:$A$10,LAYOUT_CD!$B$2:$B$10) -> 10 | I34: =STOCK_ACTUAL!F31 -> 0.070902686 | J34: =STOCK_ACTUAL!G31 -> 25.781991 | K34: =$D34*$G34 -> 720 | L34: =IF($G34>$P$1,"SÍ","NO") -> NO | M34: =IF(AND($E34="A",$L34="SÍ"),"SÍ","NO") -> NO | P34: {=INDEX($A$5:$A$104,MATCH(LARGE($D$5:$D$104-ROW($D$5:$D$104)/100000,ROW()-31),$D$5:$D$104-ROW($D$5:$D$104)/100000,0))} -> SKU00026 | Q34: =LARGE($D$5:$D$104,ROW()-31) -> 484 | R34: =SUM($Q$32:$Q34)/$S$8 -> 0.049177576 | S34: =_xlfn.XLOOKUP($P34,$A$5:$A$104,$F$5:$F$104) -> 6. RACK COLGANTES | T34: =_xlfn.XLOOKUP($P34,$A$5:$A$104,$G$5:$G$104) -> 3.61
A35: =STOCK_ACTUAL!B32 -> SKU00031 | B35: =STOCK_ACTUAL!C32 -> Marca A | C35: =STOCK_ACTUAL!D32 -> Filtros | D35: =_xlfn.XLOOKUP($A35,ROTACIÓN!$A$2:$A$101,ROTACIÓN!$B$2:$B$101) -> 135 | E35: =_xlfn.XLOOKUP($A35,ROTACIÓN!$A$2:$A$101,ROTACIÓN!$C$2:$C$101) -> C | F35: =STOCK_ACTUAL!E32 -> 8. CLUSTER | G35: =_xlfn.XLOOKUP($F35,LAYOUT_CD!$A$2:$A$10,LAYOUT_CD!$C$2:$C$10) -> 4.01 | H35: =_xlfn.XLOOKUP($F35,LAYOUT_CD!$A$2:$A$10,LAYOUT_CD!$B$2:$B$10) -> 50 | I35: =STOCK_ACTUAL!F32 -> 0.32339518 | J35: =STOCK_ACTUAL!G32 -> 21.161845 | K35: =$D35*$G35 -> 541.35 | L35: =IF($G35>$P$1,"SÍ","NO") -> SÍ | M35: =IF(AND($E35="A",$L35="SÍ"),"SÍ","NO") -> NO | P35: {=INDEX($A$5:$A$104,MATCH(LARGE($D$5:$D$104-ROW($D$5:$D$104)/100000,ROW()-31),$D$5:$D$104-ROW($D$5:$D$104)/100000,0))} -> SKU00069 | Q35: =LARGE($D$5:$D$104,ROW()-31) -> 479 | R35: =SUM($Q$32:$Q35)/$S$8 -> 0.065256798 | S35: =_xlfn.XLOOKUP($P35,$A$5:$A$104,$F$5:$F$104) -> 10. UBICACIÓN RECIBO | T35: =_xlfn.XLOOKUP($P35,$A$5:$A$104,$G$5:$G$104) -> 2.01
A36: =STOCK_ACTUAL!B33 -> SKU00032 | B36: =STOCK_ACTUAL!C33 -> Marca B | C36: =STOCK_ACTUAL!D33 -> Lubricantes | D36: =_xlfn.XLOOKUP($A36,ROTACIÓN!$A$2:$A$101,ROTACIÓN!$B$2:$B$101) -> 296 | E36: =_xlfn.XLOOKUP($A36,ROTACIÓN!$A$2:$A$101,ROTACIÓN!$C$2:$C$101) -> B | F36: =STOCK_ACTUAL!E33 -> 2. PISO | G36: =_xlfn.XLOOKUP($F36,LAYOUT_CD!$A$2:$A$10,LAYOUT_CD!$C$2:$C$10) -> 1.6 | H36: =_xlfn.XLOOKUP($F36,LAYOUT_CD!$A$2:$A$10,LAYOUT_CD!$B$2:$B$10) -> 10 | I36: =STOCK_ACTUAL!F33 -> 0.12673586 | J36: =STOCK_ACTUAL!G33 -> 11.494337 | K36: =$D36*$G36 -> 473.6 | L36: =IF($G36>$P$1,"SÍ","NO") -> NO | M36: =IF(AND($E36="A",$L36="SÍ"),"SÍ","NO") -> NO | P36: {=INDEX($A$5:$A$104,MATCH(LARGE($D$5:$D$104-ROW($D$5:$D$104)/100000,ROW()-31),$D$5:$D$104-ROW($D$5:$D$104)/100000,0))} -> SKU00005 | Q36: =LARGE($D$5:$D$104,ROW()-31) -> 465 | R36: =SUM($Q$32:$Q36)/$S$8 -> 0.080866062 | S36: =_xlfn.XLOOKUP($P36,$A$5:$A$104,$F$5:$F$104) -> 2. PISO | T36: =_xlfn.XLOOKUP($P36,$A$5:$A$104,$G$5:$G$104) -> 1.6
A37: =STOCK_ACTUAL!B34 -> SKU00033 | B37: =STOCK_ACTUAL!C34 -> Marca C | C37: =STOCK_ACTUAL!D34 -> Pastillas | D37: =_xlfn.XLOOKUP($A37,ROTACIÓN!$A$2:$A$101,ROTACIÓN!$B$2:$B$101) -> 201 | E37: =_xlfn.XLOOKUP($A37,ROTACIÓN!$A$2:$A$101,ROTACIÓN!$C$2:$C$101) -> C | F37: =STOCK_ACTUAL!E34 -> 2. PISO | G37: =_xlfn.XLOOKUP($F37,LAYOUT_CD!$A$2:$A$10,LAYOUT_CD!$C$2:$C$10) -> 1.6 | H37: =_xlfn.XLOOKUP($F37,LAYOUT_CD!$A$2:$A$10,LAYOUT_CD!$B$2:$B$10) -> 10 | I37: =STOCK_ACTUAL!F34 -> 0.079273217 | J37: =STOCK_ACTUAL!G34 -> 6.4333357 | K37: =$D37*$G37 -> 321.6 | L37: =IF($G37>$P$1,"SÍ","NO") -> NO | M37: =IF(AND($E37="A",$L37="SÍ"),"SÍ","NO") -> NO | P37: {=INDEX($A$5:$A$104,MATCH(LARGE($D$5:$D$104-ROW($D$5:$D$104)/100000,ROW()-31),$D$5:$D$104-ROW($D$5:$D$104)/100000,0))} -> SKU00100 | Q37: =LARGE($D$5:$D$104,ROW()-31) -> 460 | R37: =SUM($Q$32:$Q37)/$S$8 -> 0.096307486 | S37: =_xlfn.XLOOKUP($P37,$A$5:$A$104,$F$5:$F$104) -> 2. PISO | T37: =_xlfn.XLOOKUP($P37,$A$5:$A$104,$G$5:$G$104) -> 1.6
A38: =STOCK_ACTUAL!B35 -> SKU00034 | B38: =STOCK_ACTUAL!C35 -> Marca D | C38: =STOCK_ACTUAL!D35 -> Correas | D38: =_xlfn.XLOOKUP($A38,ROTACIÓN!$A$2:$A$101,ROTACIÓN!$B$2:$B$101) -> 431 | E38: =_xlfn.XLOOKUP($A38,ROTACIÓN!$A$2:$A$101,ROTACIÓN!$C$2:$C$101) -> A | F38: =STOCK_ACTUAL!E35 -> 7. MEZANNINE | G38: =_xlfn.XLOOKUP($F38,LAYOUT_CD!$A$2:$A$10,LAYOUT_CD!$C$2:$C$10) -> 6.42 | H38: =_xlfn.XLOOKUP($F38,LAYOUT_CD!$A$2:$A$10,LAYOUT_CD!$B$2:$B$10) -> 80 | I38: =STOCK_ACTUAL!F35 -> 0.47699849 | J38: =STOCK_ACTUAL!G35 -> 17.211951 | K38: =$D38*$G38 -> 2767.02 | L38: =IF($G38>$P$1,"SÍ","NO") -> SÍ | M38: =IF(AND($E38="A",$L38="SÍ"),"SÍ","NO") -> SÍ | P38: {=INDEX($A$5:$A$104,MATCH(LARGE($D$5:$D$104-ROW($D$5:$D$104)/100000,ROW()-31),$D$5:$D$104-ROW($D$5:$D$104)/100000,0))} -> SKU00062 | Q38: =LARGE($D$5:$D$104,ROW()-31) -> 453 | R38: =SUM($Q$32:$Q38)/$S$8 -> 0.11151393 | S38: =_xlfn.XLOOKUP($P38,$A$5:$A$104,$F$5:$F$104) -> 2. PISO | T38: =_xlfn.XLOOKUP($P38,$A$5:$A$104,$G$5:$G$104) -> 1.6
A39: =STOCK_ACTUAL!B36 -> SKU00035 | B39: =STOCK_ACTUAL!C36 -> Marca E | C39: =STOCK_ACTUAL!D36 -> Soportes | D39: =_xlfn.XLOOKUP($A39,ROTACIÓN!$A$2:$A$101,ROTACIÓN!$B$2:$B$101) -> 448 | E39: =_xlfn.XLOOKUP($A39,ROTACIÓN!$A$2:$A$101,ROTACIÓN!$C$2:$C$101) -> A | F39: =STOCK_ACTUAL!E36 -> 5. RACK SIMPLE | G39: =_xlfn.XLOOKUP($F39,LAYOUT_CD!$A$2:$A$10,LAYOUT_CD!$C$2:$C$10) -> 5.63 | H39: =_xlfn.XLOOKUP($F39,LAYOUT_CD!$A$2:$A$10,LAYOUT_CD!$B$2:$B$10) -> 65 | I39: =STOCK_ACTUAL!F36 -> 0.48453441 | J39: =STOCK_ACTUAL!G36 -> 47.17403 | K39: =$D39*$G39 -> 2522.24 | L39: =IF($G39>$P$1,"SÍ","NO") -> SÍ | M39: =IF(AND($E39="A",$L39="SÍ"),"SÍ","NO") -> SÍ | P39: {=INDEX($A$5:$A$104,MATCH(LARGE($D$5:$D$104-ROW($D$5:$D$104)/100000,ROW()-31),$D$5:$D$104-ROW($D$5:$D$104)/100000,0))} -> SKU00054 | Q39: =LARGE($D$5:$D$104,ROW()-31) -> 452 | R39: =SUM($Q$32:$Q39)/$S$8 -> 0.12668681 | S39: =_xlfn.XLOOKUP($P39,$A$5:$A$104,$F$5:$F$104) -> 5. RACK SIMPLE | T39: =_xlfn.XLOOKUP($P39,$A$5:$A$104,$G$5:$G$104) -> 5.63
A40: =STOCK_ACTUAL!B37 -> SKU00036 | B40: =STOCK_ACTUAL!C37 -> Marca A | C40: =STOCK_ACTUAL!D37 -> Filtros | D40: =_xlfn.XLOOKUP($A40,ROTACIÓN!$A$2:$A$101,ROTACIÓN!$B$2:$B$101) -> 338 | E40: =_xlfn.XLOOKUP($A40,ROTACIÓN!$A$2:$A$101,ROTACIÓN!$C$2:$C$101) -> B | F40: =STOCK_ACTUAL!E37 -> 8. CLUSTER | G40: =_xlfn.XLOOKUP($F40,LAYOUT_CD!$A$2:$A$10,LAYOUT_CD!$C$2:$C$10) -> 4.01 | H40: =_xlfn.XLOOKUP($F40,LAYOUT_CD!$A$2:$A$10,LAYOUT_CD!$B$2:$B$10) -> 50 | I40: =STOCK_ACTUAL!F37 -> 0.41377881 | J40: =STOCK_ACTUAL!G37 -> 16.498545 | K40: =$D40*$G40 -> 1355.38 | L40: =IF($G40>$P$1,"SÍ","NO") -> SÍ | M40: =IF(AND($E40="A",$L40="SÍ"),"SÍ","NO") -> NO | P40: {=INDEX($A$5:$A$104,MATCH(LARGE($D$5:$D$104-ROW($D$5:$D$104)/100000,ROW()-31),$D$5:$D$104-ROW($D$5:$D$104)/100000,0))} -> SKU00018 | Q40: =LARGE($D$5:$D$104,ROW()-31) -> 451 | R40: =SUM($Q$32:$Q40)/$S$8 -> 0.14182612 | S40: =_xlfn.XLOOKUP($P40,$A$5:$A$104,$F$5:$F$104) -> 2. PISO | T40: =_xlfn.XLOOKUP($P40,$A$5:$A$104,$G$5:$G$104) -> 1.6
A41: =STOCK_ACTUAL!B38 -> SKU00037 | B41: =STOCK_ACTUAL!C38 -> Marca B | C41: =STOCK_ACTUAL!D38 -> Lubricantes | D41: =_xlfn.XLOOKUP($A41,ROTACIÓN!$A$2:$A$101,ROTACIÓN!$B$2:$B$101) -> 294 | E41: =_xlfn.XLOOKUP($A41,ROTACIÓN!$A$2:$A$101,ROTACIÓN!$C$2:$C$101) -> B | F41: =STOCK_ACTUAL!E38 -> 7. MEZANNINE | G41: =_xlfn.XLOOKUP($F41,LAYOUT_CD!$A$2:$A$10,LAYOUT_CD!$C$2:$C$10) -> 6.42 | H41: =_xlfn.XLOOKUP($F41,LAYOUT_CD!$A$2:$A$10,LAYOUT_CD!$B$2:$B$10) -> 80 | I41: =STOCK_ACTUAL!F38 -> 0.1870762 | J41: =STOCK_ACTUAL!G38 -> 26.180136 | K41: =$D41*$G41 -> 1887.48 | L41: =IF($G41>$P$1,"SÍ","NO") -> SÍ | M41: =IF(AND($E41="A",$L41="SÍ"),"SÍ","NO") -> NO | P41: {=INDEX($A$5:$A$104,MATCH(LARGE($D$5:$D$104-ROW($D$5:$D$104)/100000,ROW()-31),$D$5:$D$104-ROW($D$5:$D$104)/100000,0))} -> SKU00030 | Q41: =LARGE($D$5:$D$104,ROW()-31) -> 450 | R41: =SUM($Q$32:$Q41)/$S$8 -> 0.15693186 | S41: =_xlfn.XLOOKUP($P41,$A$5:$A$104,$F$5:$F$104) -> 2. PISO | T41: =_xlfn.XLOOKUP($P41,$A$5:$A$104,$G$5:$G$104) -> 1.6
...

Sheet DASHBOARD_EJECUTIVO
A1: SISTEMA INTELIGENTE DE RESLOTTING — MVP DE DIAGNÓSTICO ANALÍTICO | BA1: DATOS DE APOYO PARA GRÁFICOS (no imprimir)
A2: Inchcape Perú | CD Aldeas | Repuestos automotrices | Muestra académica: 100 SKU de un universo de +55,000
A3: Todos los gráficos se alimentan de fórmulas en ANALYTICS_BASE, que referencian únicamente las hojas fuente del archivo. Sin datos externos ni supuestos inventados. | BA3: G10 — Scatter: Rotación vs Tiempo | BE3: G11 — Boxplot PESO (base + cajas + bigotes) | BL3: G4 - Rotación y tiempo por zona
